Workbook

Sheet Sheet1
C1: Premier League | E1: Europe | G1: FA Cup | I1: EFL Cup | K1: Community Shield | M1: Total
A2: # | B2: Name | C2: Apps | D2: Goals | E2: Apps | F2: Goals | G2: Apps | H2: Goals | I2: Apps | J2: Goals | K2: Apps | L2: Goals | M2: Apps | N2: Goals
A3: 1 | B3: CECH Petr | C3: 103 | D3: 0 | E3: 8 | F3: 0 | G3: 3 | H3: 0 | I3: 1 | J3: 0 | K3: 2 | L3: 0 | M3: 117 | N3: 0
A4: 2 | B4: BELLERIN Hector | C4: 122 | D4: 6 | E4: 21 | F4: 1 | G4: 8 | H4: 0 | I4: 3 | J4: 0 | K4: 2 | L4: 0 | M4: 156 | N4: 7
A5: 4 | B5: ELNENY Mohamed | C5: 37 | D5: 0 | E5: 17 | F5: 2 | G5: 7 | H5: 0 | I5: 7 | J5: 0 | K5: 1 | L5: 0 | M5: 69 | N5: 2
A6: 6 | B6: KOSCIELNY Laurent | C6: 238 | D6: 19 | E6: 48 | F6: 2 | G6: 22 | H6: 1 | I6: 10 | J6: 2 | K6: 2 | L6: 0 | M6: 320 | N6: 24
A7: 7 | B7: MKHITARYAN Henrikh | C7: 11 | D7: 2 | E7: 5 | F7: 1 | G7: 0 | H7: 0 | I7: 0 | J7: 0 | K7: 0 | L7: 0 | M7: 16 | N7: 3
A8: 8 | B8: RAMSEY Aaron | C8: 235 | D8: 36 | E8: 54 | F8: 15 | G8: 25 | H8: 6 | I8: 11 | J8: 0 | K8: 2 | L8: 1 | M8: 327 | N8: 58
A9: 9 | B9: LACAZETTE Alexandre | C9: 31 | D9: 14 | E9: 2 | F9: 2 | G9: 0 | H9: 0 | I9: 1 | J9: 0 | K9: 1 | L9: 0 | M9: 35 | N9: 16
A10: 10 | B10: WILSHERE Jack | C10: 125 | D10: 7 | E10: 38 | F10: 5 | G10: 13 | H10: 1 | I10: 17 | J10: 1 | K10: 1 | L10: 0 | M10: 194 | N10: 14
A11: 11 | B11: OZIL Mesut | C11: 142 | D11: 27 | E11: 34 | F11: 8 | G11: 15 | H11: 2 | I11: 2 | J11: 0 | K11: 1 | L11: 0 | M11: 194 | N11: 37
A12: 12 | B12: LICHSTEINER Stephan | C12: 0 | D12: 0 | E12: 0 | F12: 0 | G12: 0 | H12: 0 | I12: 0 | J12: 0 | K12: 0 | L12: 0 | M12: 0 | N12: 0
A13: 13 | B13: OSPINA David | C13: 28 | D13: 0 | E13: 21 | F13: 0 | G13: 10 | H13: 0 | I13: 6 | J13: 0 | K13: 0 | L13: 0 | M13: 65 | N13: 0
A14: 14 | B14: AUBAMEYANG Pierre-Emerick | C14: 13 | D14: 10 | E14: 0 | F14: 0 | G14: 0 | H14: 0 | I14: 1 | J14: 0 | K14: 0 | L14: 0 | M14: 14 | N14: 10
... A24: 27 | B24: MAVROPANOS Konstantinos | C24: 3 | D24: 0 | E24: 0 | F24: 0 | G24: 0 | H24: 0 | I24: 0 | J24: 0 | K24: 0 | L24: 0 | M24: 3 | N24: 0
A25: - | B25: CAMPBELL Joel | C25: 23 | D25: 3 | E25: 8 | F25: 0 | G25: 4 | H25: 1 | I25: 3 | J25: 0 | K25: 1 | L25: 0 | M25: 39 | N25: 4
A26: 28 | B26: PEREZ Lucas | C26: 12 | D26: 1 | E26: 3 | F26: 3 | G26: 4 | H26: 1 | I26: 3 | J26: 2 | K26: 0 | L26: 0 | M26: 22 | N26: 7
A27: 30 | B27: MAITLAND-NILES Ainsley | C27: 18 | D27: 0 | E27: 10 | F27: 0 | G27: 5 | H27: 0 | I27: 6 | J27: 0 | K27: 0 | L27: 0 | M27: 39 | N27: 0
A28: 31 | B28: KOLASINAC Sead | C28: 26 | D28: 2 | E28: 5 | F28: 2 | G28: 0 | H28: 0 | I28: 2 | J28: 0 | K28: 1 | L28: 1 | M28: 34 | N28: 5
A29: 32 | B29: AKPOM Chuba | C29: 3 | D29: 0 | E29: 0 | F29: 0 | G29: 4 | H29: 0 | I29: 3 | J29: 0 | K29: 0 | L29: 0 | M29: 10 | N29: 0
A30: 34 | B30: XHAKA Granit | C30: 70 | D30: 3 | E30: 11 | F30: 2 | G30: 5 | H30: 0 | I30: 4 | J30: 1 | K30: 1 | L30: 0 | M30: 91 | N30: 6
A31: 37 | B31: BIELIK Krystian | C31: 0 | D31: 0 | E31: 0 | F31: 0 | G31: 0 | H31: 0 | I31: 2 | J31: 0 | K31: 0 | L31: 0 | M31: 2 | N31: 0
A32: 40 | B32: ZELALEM Gedion | C32: 0 | D32: 0 | E32: 1 | F32: 0 | G32: 0 | H32: 0 | I32: 3 | J32: 0 | K32: 0 | L32: 0 | M32: 4 | N32: 0
A33: 43 | B33: DA SILVA Joshua | C33: 0 | D33: 0 | E33: 0 | F33: 0 | G33: 0 | H33: 0 | I33: 3 | J33: 0 | K33: 0 | L33: 0 | M33: 3 | N33: 0
A34: 54 | B34: MACEY Matt | C34: 0 | D34: 0 | E34: 0 | F34: 0 | G34: 0 | H34: 0 | I34: 1 | J34: 0 | K34: 0 | L34: 0 | M34: 1 | N34: 0
A35: 61 | B35: NELSON Reiss | C35: 0 | D35: 0 | E35: 8 | F35: 0 | G35: 0 | H35: 0 | I35: 3 | J35: 0 | K35: 1 | L35: 0 | M35: 12 | N35: 0
A36: 62 | B36: NKETIAH Eddie | C36: 0 | D36: 0 | E36: 5 | F36: 0 | G36: 0 | H36: 0 | I36: 1 | J36: 2 | K36: 0 | L36: 0 | M36: 6 | N36: 2
A37: 65 | B37: SHEAF Ben | C37: 0 | D37: 0 | E37: 1 | F37: 0 | G37: 0 | H37: 0 | I37: 1 | J37: 0 | K37: 0 | L37: 0 | M37: 2 | N37: 0
A38: 69 | B38: WILLOCK Joe | C38: 0 | D38: 0 | E38: 5 | F38: 0 | G38: 0 | H38: 0 | I38: 3 | J38: 0 | K38: 0 | L38: 0 | M38: 8 | N38: 0

Sheet #
B3: PREMIER LEAGUE | N3: EUROPE | Z3: FA CUP | AL3: LEAGUE CUP
AX4: COMMUNITY SHIELD
A5: nr | B5: name | Z5: name | AL5: name
A6: 1 | B6: RAYA David | C6: 107 | D6: 0 | E6: 0 | G6: ='Apps & Goals 26-27'!C4 -> 6 | H6: ='Apps & Goals 26-27'!D4 -> 0 | I6: ='Apps & Goals 26-27'!E4 -> 0 | J6: =G6+C6 -> 113 | K6: =H6+D6 -> 0 | L6: =I6+E6 -> 0 | M6: 1 | N6: RAYA David | O6: 36 | P6: 0 | Q6: 0 | S6: ='Apps & Goals 26-27'!F4 -> 1 | T6: ='Apps & Goals 26-27'!G4 -> 0 | U6: ='Apps & Goals 26-27'!H4 -> 0 | V6: =S6+O6 -> 37 | W6: =T6+P6 -> 0 | X6: =U6+Q6 -> 0 | Z6: RAYA David | AA6: 1 | AB6: 0 | AC6: 0 | AE6: ='Apps & Goals 26-27'!I4 -> 0 | AF6: ='Apps & Goals 26-27'!J4 -> 0 | AG6: ='Apps & Goals 26-27'!K4 -> 0 | AH6: =AE6+AA6 -> 1 | AI6: =AF6+AB6 -> 0 | AJ6: =AG6+AC6 -> 0 | AL6: RAYA David | AM6: 3 | AN6: 0 | AO6: 0 | AQ6: ='Apps & Goals 26-27'!L4 -> 0 | AR6: ='Apps & Goals 26-27'!M4 -> 0 | AS6: ='Apps & Goals 26-27'!N4 -> 0 | AT6: =AQ6+AM6 -> 3 | AU6: =AR6+AN6 -> 0 | AV6: =AS6+AO6 -> 0 | AX6: RAYA David | AY6: 0 | AZ6: 0 | BA6: 0 | BC6: ='Apps & Goals 26-27'!O4 -> 1 | BD6: ='Apps & Goals 26-27'!P4 -> 0 | BE6: ='Apps & Goals 26-27'!Q4 -> 0 | BF6: =BC6+AY6 -> 1 | BG6: =BD6+AZ6 -> 0 | BH6: =BE6+BA6 -> 0
A7: 2 | B7: SALIBA William | C7: 131 | D7: 7 | E7: 2 | G7: ='Apps & Goals 26-27'!C5 -> 0 | H7: ='Apps & Goals 26-27'!D5 -> 0 | I7: ='Apps & Goals 26-27'!E5 -> 0 | J7: =G7+C7 -> 131 | K7: =H7+D7 -> 7 | L7: =I7+E7 -> 2 | M7: 2 | N7: SALIBA William | O7: 37 | P7: 1 | Q7: 0 | S7: ='Apps & Goals 26-27'!F5 -> 0 | T7: ='Apps & Goals 26-27'!G5 -> 0 | U7: ='Apps & Goals 26-27'!H5 -> 0 | V7: =S7+O7 -> 37 | W7: =T7+P7 -> 1 | X7: =U7+Q7 -> 0 | Z7: SALIBA William | AA7: 5 | AB7: 0 | AC7: 0 | AE7: ='Apps & Goals 26-27'!I5 -> 0 | AF7: ='Apps & Goals 26-27'!J5 -> 0 | AG7: ='Apps & Goals 26-27'!K5 -> 0 | AH7: =AE7+AA7 -> 5 | AI7: =AF7+AB7 -> 0 | AJ7: =AG7+AC7 -> 0 | AL7: SALIBA William | AM7: 10 | AN7: 0 | AO7: 1 | AQ7: ='Apps & Goals 26-27'!L5 -> 0 | AR7: ='Apps & Goals 26-27'!M5 -> 0 | AS7: ='Apps & Goals 26-27'!N5 -> 0 | AT7: =AQ7+AM7 -> 10 | AU7: =AR7+AN7 -> 0 | AV7: =AS7+AO7 -> 1 | AX7: SALIBA William | AY7: 1 | AZ7: 0 | BA7: 0 | BC7: ='Apps & Goals 26-27'!O5 -> 0 | BD7: ='Apps & Goals 26-27'!P5 -> 0 | BE7: ='Apps & Goals 26-27'!Q5 -> 0 | BF7: =BC7+AY7 -> 1 | BG7: =BD7+AZ7 -> 0 | BH7: =BE7+BA7 -> 0
A8: 3 | B8: MOSQUERA Cristhian | C8: 20 | D8: 0 | E8: 0 | G8: ='Apps & Goals 26-27'!C6 -> 2 | H8: ='Apps & Goals 26-27'!D6 -> 0 | I8: ='Apps & Goals 26-27'!E6 -> 0 | J8: =G8+C8 -> 22 | K8: =H8+D8 -> 0 | L8: =I8+E8 -> 0 | M8: 3 | N8: MOSQUERA Cristhian | O8: 10 | P8: 0 | Q8: 0 | S8: ='Apps & Goals 26-27'!F6 -> 0 | T8: ='Apps & Goals 26-27'!G6 -> 0 | U8: ='Apps & Goals 26-27'!H6 -> 0 | V8: =S8+O8 -> 10 | W8: =T8+P8 -> 0 | X8: =U8+Q8 -> 0 | Z8: MOSQUERA Cristhian | AA8: 3 | AB8: 0 | AC8: 0 | AE8: ='Apps & Goals 26-27'!I6 -> 0 | AF8: ='Apps & Goals 26-27'!J6 -> 0 | AG8: ='Apps & Goals 26-27'!K6 -> 0 | AH8: =AE8+AA8 -> 3 | AI8: =AF8+AB8 -> 0 | AJ8: =AG8+AC8 -> 0 | AL8: MOSQUERA Cristhian | AM8: 2 | AN8: 0 | AO8: 0 | AQ8: ='Apps & Goals 26-27'!L6 -> 0 | AR8: ='Apps & Goals 26-27'!M6 -> 0 | AS8: ='Apps & Goals 26-27'!N6 -> 0 | AT8: =AQ8+AM8 -> 2 | AU8: =AR8+AN8 -> 0 | AV8: =AS8+AO8 -> 0 | AX8: MOSQUERA Cristhian | AY8: 0 | AZ8: 0 | BA8: 0 | BC8: ='Apps & Goals 26-27'!O6 -> 1 | BD8: ='Apps & Goals 26-27'!P6 -> 0 | BE8: ='Apps & Goals 26-27'!Q6 -> 0 | BF8: =BC8+AY8 -> 1 | BG8: =BD8+AZ8 -> 0 | BH8: =BE8+BA8 -> 0
A9: 4 | B9: WHITE Ben | C9: 136 | D9: 6 | E9: 12 | G9: ='Apps & Goals 26-27'!C7 -> 5 | H9: ='Apps & Goals 26-27'!D7 -> 0 | I9: ='Apps & Goals 26-27'!E7 -> 2 | J9: =G9+C9 -> 141 | K9: =H9+D9 -> 6 | L9: =I9+E9 -> 14 | M9: 4 | N9: WHITE Ben | O9: 37 | P9: 0 | Q9: 2 | S9: ='Apps & Goals 26-27'!F7 -> 1 | T9: ='Apps & Goals 26-27'!G7 -> 0 | U9: ='Apps & Goals 26-27'!H7 -> 0 | V9: =S9+O9 -> 38 | W9: =T9+P9 -> 0 | X9: =U9+Q9 -> 2 | Z9: WHITE Ben | AA9: 6 | AB9: 0 | AC9: 0 | AE9: ='Apps & Goals 26-27'!I7 -> 0 | AF9: ='Apps & Goals 26-27'!J7 -> 0 | AG9: ='Apps & Goals 26-27'!K7 -> 0 | AH9: =AE9+AA9 -> 6 | AI9: =AF9+AB9 -> 0 | AJ9: =AG9+AC9 -> 0 | AL9: WHITE Ben | AM9: 10 | AN9: 1 | AO9: 0 | AQ9: ='Apps & Goals 26-27'!L7 -> 0 | AR9: ='Apps & Goals 26-27'!M7 -> 0 | AS9: ='Apps & Goals 26-27'!N7 -> 0 | AT9: =AQ9+AM9 -> 10 | AU9: =AR9+AN9 -> 1 | AV9: =AS9+AO9 -> 0 | AX9: WHITE Ben | AY9: 1 | AZ9: 0 | BA9: 0 | BC9: ='Apps & Goals 26-27'!O7 -> 1 | BD9: ='Apps & Goals 26-27'!P7 -> 0 | BE9: ='Apps & Goals 26-27'!Q7 -> 0 | BF9: =BC9+AY9 -> 2 | BG9: =BD9+AZ9 -> 0 | BH9: =BE9+BA9 -> 0
A10: 5 | B10: HINCAPIE Piero | C10: 25 | D10: 1 | E10: 2 | G10: ='Apps & Goals 26-27'!C8 -> 3 | H10: ='Apps & Goals 26-27'!D8 -> 0 | I10: ='Apps & Goals 26-27'!E8 -> 0 | J10: =G10+C10 -> 28 | K10: =H10+D10 -> 1 | L10: =I10+E10 -> 2 | M10: 5 | N10: HINCAPIE Piero | O10: 10 | P10: 0 | Q10: 0 | S10: ='Apps & Goals 26-27'!F8 -> 1 | T10: ='Apps & Goals 26-27'!G8 -> 0 | U10: ='Apps & Goals 26-27'!H8 -> 0 | V10: =S10+O10 -> 11 | W10: =T10+P10 -> 0 | X10: =U10+Q10 -> 0 | Z10: HINCAPIE Piero | AA10: 1 | AB10: 0 | AC10: 0 | AE10: ='Apps & Goals 26-27'!I8 -> 0 | AF10: ='Apps & Goals 26-27'!J8 -> 0 | AG10: ='Apps & Goals 26-27'!K8 -> 0 | AH10: =AE10+AA10 -> 1 | AI10: =AF10+AB10 -> 0 | AJ10: =AG10+AC10 -> 0 | AL10: HINCAPIE Piero | AM10: 3 | AN10: 0 | AO10: 0 | AQ10: ='Apps & Goals 26-27'!L8 -> 0 | AR10: ='Apps & Goals 26-27'!M8 -> 0 | AS10: ='Apps & Goals 26-27'!N8 -> 0 | AT10: =AQ10+AM10 -> 3 | AU10: =AR10+AN10 -> 0 | AV10: =AS10+AO10 -> 0 | AX10: HINCAPIE Piero | AY10: 0 | AZ10: 0 | BA10: 0 | BC10: ='Apps & Goals 26-27'!O8 -> 1 | BD10: ='Apps & Goals 26-27'!P8 -> 0 | BE10: ='Apps & Goals 26-27'!Q8 -> 0 | BF10: =BC10+AY10 -> 1 | BG10: =BD10+AZ10 -> 0 | BH10: =BE10+BA10 -> 0
A11: 6 | B11: GABRIEL | C11: 192 | D11: 20 | E11: 5 | G11: ='Apps & Goals 26-27'!C9 -> 6 | H11: ='Apps & Goals 26-27'!D9 -> 0 | I11: ='Apps & Goals 26-27'!E9 -> 0 | J11: =G11+C11 -> 198 | K11: =H11+D11 -> 20 | L11: =I11+E11 -> 5 | M11: 6 | N11: GABRIEL | O11: 44 | P11: 3 | Q11: 1 | S11: ='Apps & Goals 26-27'!F9 -> 1 | T11: ='Apps & Goals 26-27'!G9 -> 0 | U11: ='Apps & Goals 26-27'!H9 -> 0 | V11: =S11+O11 -> 45 | W11: =T11+P11 -> 3 | X11: =U11+Q11 -> 1 | Z11: GABRIEL | AA11: 7 | AB11: 1 | AC11: 0 | AE11: ='Apps & Goals 26-27'!I9 -> 0 | AF11: ='Apps & Goals 26-27'!J9 -> 0 | AG11: ='Apps & Goals 26-27'!K9 -> 0 | AH11: =AE11+AA11 -> 7 | AI11: =AF11+AB11 -> 1 | AJ11: =AG11+AC11 -> 0 | AL11: GABRIEL | AM11: 17 | AN11: 0 | AO11: 0 | AQ11: ='Apps & Goals 26-27'!L9 -> 1 | AR11: ='Apps & Goals 26-27'!M9 -> 0 | AS11: ='Apps & Goals 26-27'!N9 -> 0 | AT11: =AQ11+AM11 -> 18 | AU11: =AR11+AN11 -> 0 | AV11: =AS11+AO11 -> 0 | AX11: GABRIEL | AY11: 1 | AZ11: 0 | BA11: 0 | BC11: ='Apps & Goals 26-27'!O9 -> 1 | BD11: ='Apps & Goals 26-27'!P9 -> 0 | BE11: ='Apps & Goals 26-27'!Q9 -> 0 | BF11: =BC11+AY11 -> 2 | BG11: =BD11+AZ11 -> 0 | BH11: =BE11+BA11 -> 0
A12: 7 | B12: SAKA Bukayo | C12: 226 | D12: 60 | E12: 50 | G12: ='Apps & Goals 26-27'!C10 -> 6 | H12: ='Apps & Goals 26-27'!D10 -> 3 | I12: ='Apps & Goals 26-27'!E10 -> 0 | J12: =G12+C12 -> 232 | K12: =H12+D12 -> 63 | L12: =I12+E12 -> 50 | M12: 7 | N12: SAKA Bukayo | O12: 54 | P12: 18 | Q12: 15 | S12: ='Apps & Goals 26-27'!F10 -> 1 | T12: ='Apps & Goals 26-27'!G10 -> 0 | U12: ='Apps & Goals 26-27'!H10 -> 0 | V12: =S12+O12 -> 55 | W12: =T12+P12 -> 18 | X12: =U12+Q12 -> 15 | Z12: SAKA Bukayo | AA12: 13 | AB12: 1 | AC12: 1 | AE12: ='Apps & Goals 26-27'!I10 -> 0 | AF12: ='Apps & Goals 26-27'!J10 -> 0 | AG12: ='Apps & Goals 26-27'!K10 -> 0 | AH12: =AE12+AA12 -> 13 | AI12: =AF12+AB12 -> 1 | AJ12: =AG12+AC12 -> 1 | AL12: SAKA Bukayo | AM12: 17 | AN12: 2 | AO12: 2 | AQ12: ='Apps & Goals 26-27'!L10 -> 0 | AR12: ='Apps & Goals 26-27'!M10 -> 0 | AS12: ='Apps & Goals 26-27'!N10 -> 0 | AT12: =AQ12+AM12 -> 17 | AU12: =AR12+AN12 -> 2 | AV12: =AS12+AO12 -> 2 | AX12: SAKA Bukayo | AY12: 2 | AZ12: 0 | BA12: 2 | BC12: ='Apps & Goals 26-27'!O10 -> 1 | BD12: ='Apps & Goals 26-27'!P10 -> 0 | BE12: ='Apps & Goals 26-27'!Q10 -> 0 | BF12: =BC12+AY12 -> 3 | BG12: =BD12+AZ12 -> 0 | BH12: =BE12+BA12 -> 2
A13: 8 | B13: ODEGAARD Martin | C13: 176 | D13: 35 | E13: 37 | G13: ='Apps & Goals 26-27'!C11 -> 6 | H13: ='Apps & Goals 26-27'!D11 -> 2 | I13: ='Apps & Goals 26-27'!E11 -> 0 | J13: =G13+C13 -> 182 | K13: =H13+D13 -> 37 | L13: =I13+E13 -> 37 | M13: 8 | N13: ODEGAARD Martin | O13: 41 | P13: 6 | Q13: 3 | S13: ='Apps & Goals 26-27'!F11 -> 1 | T13: ='Apps & Goals 26-27'!G11 -> 1 | U13: ='Apps & Goals 26-27'!H11 -> 0 | V13: =S13+O13 -> 42 | W13: =T13+P13 -> 7 | X13: =U13+Q13 -> 3 | Z13: ODEGAARD Martin | AA13: 6 | AB13: 0 | AC13: 0 | AE13: ='Apps & Goals 26-27'!I11 -> 0 | AF13: ='Apps & Goals 26-27'!J11 -> 0 | AG13: ='Apps & Goals 26-27'!K11 -> 0 | AH13: =AE13+AA13 -> 6 | AI13: =AF13+AB13 -> 0 | AJ13: =AG13+AC13 -> 0 | AL13: ODEGAARD Martin | AM13: 10 | AN13: 1 | AO13: 3 | AQ13: ='Apps & Goals 26-27'!L11 -> 1 | AR13: ='Apps & Goals 26-27'!M11 -> 0 | AS13: ='Apps & Goals 26-27'!N11 -> 0 | AT13: =AQ13+AM13 -> 11 | AU13: =AR13+AN13 -> 1 | AV13: =AS13+AO13 -> 3 | AX13: ODEGAARD Martin | AY13: 1 | AZ13: 0 | BA13: 0 | BC13: ='Apps & Goals 26-27'!O11 -> 1 | BD13: ='Apps & Goals 26-27'!P11 -> 1 | BE13: ='Apps & Goals 26-27'!Q11 -> 0 | BF13: =BC13+AY13 -> 2 | BG13: =BD13+AZ13 -> 1 | BH13: =BE13+BA13 -> 0
A14: 10 | B14: EZE Eberechi | C14: 32 | D14: 7 | E14: 2 | G14: ='Apps & Goals 26-27'!C12 -> 4 | H14: ='Apps & Goals 26-27'!D12 -> 0 | I14: ='Apps & Goals 26-27'!E12 -> 0 | J14: =G14+C14 -> 36 | K14: =H14+D14 -> 7 | L14: =I14+E14 -> 2 | M14: 10 | N14: EZE Eberechi | O14: 13 | P14: 1 | Q14: 1 | S14: ='Apps & Goals 26-27'!F12 -> 1 | T14: ='Apps & Goals 26-27'!G12 -> 0 | U14: ='Apps & Goals 26-27'!H12 -> 0 | V14: =S14+O14 -> 14 | W14: =T14+P14 -> 1 | X14: =U14+Q14 -> 1 | Z14: EZE Eberechi | AA14: 3 | AB14: 1 | AC14: 2 | AE14: ='Apps & Goals 26-27'!I12 -> 0 | AF14: ='Apps & Goals 26-27'!J12 -> 0 | AG14: ='Apps & Goals 26-27'!K12 -> 0 | AH14: =AE14+AA14 -> 3 | AI14: =AF14+AB14 -> 1 | AJ14: =AG14+AC14 -> 2 | AL14: EZE Eberechi | AM14: 4 | AN14: 1 | AO14: 0 | AQ14: ='Apps & Goals 26-27'!L12 -> 1 | AR14: ='Apps & Goals 26-27'!M12 -> 0 | AS14: ='Apps & Goals 26-27'!N12 -> 1 | AT14: =AQ14+AM14 -> 5 | AU14: =AR14+AN14 -> 1 | AV14: =AS14+AO14 -> 1 | AX14: EZE Eberechi | AY14: 0 | AZ14: 0 | BA14: 0 | BC14: ='Apps & Goals 26-27'!O12 -> 1 | BD14: ='Apps & Goals 26-27'!P12 -> 0 | BE14: ='Apps & Goals 26-27'!Q12 -> 0 | BF14: =BC14+AY14 -> 1 | BG14: =BD14+AZ14 -> 0 | BH14: =BE14+BA14 -> 0
A15: 12 | B15: TIMBER Jurrien | C15: 62 | D15: 4 | E15: 8 | G15: ='Apps & Goals 26-27'!C13 -> 3 | H15: ='Apps & Goals 26-27'!D13 -> 0 | I15: ='Apps & Goals 26-27'!E13 -> 0 | J15: =G15+C15 -> 65 | K15: =H15+D15 -> 4 | L15: =I15+E15 -> 8 | M15: 12 | N15: TIMBER Jurrien | O15: 21 | P15: 2 | Q15: 2 | S15: ='Apps & Goals 26-27'!F13 -> 0 | T15: ='Apps & Goals 26-27'!G13 -> 0 | U15: ='Apps & Goals 26-27'!H13 -> 0 | V15: =S15+O15 -> 21 | W15: =T15+P15 -> 2 | X15: =U15+Q15 -> 2 | Z15: TIMBER Jurrien | AA15: 3 | AB15: 0 | AC15: 0 | AE15: ='Apps & Goals 26-27'!I13 -> 0 | AF15: ='Apps & Goals 26-27'!J13 -> 0 | AG15: ='Apps & Goals 26-27'!K13 -> 0 | AH15: =AE15+AA15 -> 3 | AI15: =AF15+AB15 -> 0 | AJ15: =AG15+AC15 -> 0 | AL15: TIMBER Jurrien | AM15: 8 | AN15: 0 | AO15: 0 | AQ15: ='Apps & Goals 26-27'!L13 -> 0 | AR15: ='Apps & Goals 26-27'!M13 -> 0 | AS15: ='Apps & Goals 26-27'!N13 -> 0 | AT15: =AQ15+AM15 -> 8 | AU15: =AR15+AN15 -> 0 | AV15: =AS15+AO15 -> 0 | AX15: TIMBER Jurrien | AY15: 1 | AZ15: 0 | BA15: 0 | BC15: ='Apps & Goals 26-27'!O13 -> 0 | BD15: ='Apps & Goals 26-27'!P13 -> 0 | BE15: ='Apps & Goals 26-27'!Q13 -> 0 | BF15: =BC15+AY15 -> 1 | BG15: =BD15+AZ15 -> 0 | BH15: =BE15+BA15 -> 0
A16: 13 | B16: KEPA Arrizabalaga | C16: 1 | D16: 0 | E16: 0 | G16: ='Apps & Goals 26-27'!C14 -> 0 | H16: ='Apps & Goals 26-27'!D14 -> 0 | I16: ='Apps & Goals 26-27'!E14 -> 0 | J16: =G16+C16 -> 1 | K16: =H16+D16 -> 0 | L16: =I16+E16 -> 0 | M16: 13 | N16: KEPA Arrizabalaga | O16: 1 | P16: 0 | Q16: 0 | S16: ='Apps & Goals 26-27'!F14 -> 0 | T16: ='Apps & Goals 26-27'!G14 -> 0 | U16: ='Apps & Goals 26-27'!H14 -> 0 | V16: =S16+O16 -> 1 | W16: =T16+P16 -> 0 | X16: =U16+Q16 -> 0 | Z16: KEPA Arrizabalaga | AA16: 4 | AB16: 0 | AC16: 0 | AE16: ='Apps & Goals 26-27'!I14 -> 0 | AF16: ='Apps & Goals 26-27'!J14 -> 0 | AG16: ='Apps & Goals 26-27'!K14 -> 0 | AH16: =AE16+AA16 -> 4 | AI16: =AF16+AB16 -> 0 | AJ16: =AG16+AC16 -> 0 | AL16: KEPA Arrizabalaga | AM16: 6 | AN16: 0 | AO16: 0 | AQ16: ='Apps & Goals 26-27'!L14 -> 1 | AR16: ='Apps & Goals 26-27'!M14 -> 0 | AS16: ='Apps & Goals 26-27'!N14 -> 0 | AT16: =AQ16+AM16 -> 7 | AU16: =AR16+AN16 -> 0 | AV16: =AS16+AO16 -> 0 | AX16: KEPA Arrizabalaga | AY16: 0 | AZ16: 0 | BA16: 0 | BC16: ='Apps & Goals 26-27'!O14 -> 0 | BD16: ='Apps & Goals 26-27'!P14 -> 0 | BE16: ='Apps & Goals 26-27'!Q14 -> 0 | BF16: =BC16+AY16 -> 0 | BG16: =BD16+AZ16 -> 0 | BH16: =BE16+BA16 -> 0
A17: 14 | B17: GYOKERES Viktor | C17: 36 | D17: 14 | E17: 1 | G17: ='Apps & Goals 26-27'!C15 -> 3 | H17: ='Apps & Goals 26-27'!D15 -> 0 | I17: ='Apps & Goals 26-27'!E15 -> 0 | J17: =G17+C17 -> 39 | K17: =H17+D17 -> 14 | L17: =I17+E17 -> 1 | M17: 14 | N17: GYOKERES Viktor | O17: 13 | P17: 5 | Q17: 1 | S17: ='Apps & Goals 26-27'!F15 -> 1 | T17: ='Apps & Goals 26-27'!G15 -> 0 | U17: ='Apps & Goals 26-27'!H15 -> 0 | V17: =S17+O17 -> 14 | W17: =T17+P17 -> 5 | X17: =U17+Q17 -> 1 | Z17: GYOKERES Viktor | AA17: 2 | AB17: 1 | AC17: 0 | AE17: ='Apps & Goals 26-27'!I15 -> 0 | AF17: ='Apps & Goals 26-27'!J15 -> 0 | AG17: ='Apps & Goals 26-27'!K15 -> 0 | AH17: =AE17+AA17 -> 2 | AI17: =AF17+AB17 -> 1 | AJ17: =AG17+AC17 -> 0 | AL17: GYOKERES Viktor | AM17: 4 | AN17: 1 | AO17: 1 | AQ17: ='Apps & Goals 26-27'!L15 -> 1 | AR17: ='Apps & Goals 26-27'!M15 -> 0 | AS17: ='Apps & Goals 26-27'!N15 -> 0 | AT17: =AQ17+AM17 -> 5 | AU17: =AR17+AN17 -> 1 | AV17: =AS17+AO17 -> 1 | AX17: GYOKERES Viktor | AY17: 0 | AZ17: 0 | BA17: 0 | BC17: ='Apps & Goals 26-27'!O15 -> 1 | BD17: ='Apps & Goals 26-27'!P15 -> 0 | BE17: ='Apps & Goals 26-27'!Q15 -> 0 | BF17: =BC17+AY17 -> 1 | BG17: =BD17+AZ17 -> 0 | BH17: =BE17+BA17 -> 0
... A40: 89 | B40: SALMON Marli | C40: 0 | D40: 0 | E40: 0 | G40: ='Apps & Goals 26-27'!C38 -> 0 | H40: ='Apps & Goals 26-27'!D38 -> 0 | I40: ='Apps & Goals 26-27'!E38 -> 0 | J40: =G40+C40 -> 0 | K40: =H40+D40 -> 0 | L40: =I40+E40 -> 0 | M40: 89 | N40: SALMON Marli | O40: 1 | P40: 0 | Q40: 0 | S40: ='Apps & Goals 26-27'!F38 -> 0 | T40: ='Apps & Goals 26-27'!G38 -> 0 | U40: ='Apps & Goals 26-27'!H38 -> 0 | V40: =S40+O40 -> 1 | W40: =T40+P40 -> 0 | X40: =U40+Q40 -> 0 | Z40: SALMON Marli | AA40: 3 | AB40: 0 | AC40: 0 | AE40: ='Apps & Goals 26-27'!I38 -> 0 | AF40: ='Apps & Goals 26-27'!J38 -> 0 | AG40: ='Apps & Goals 26-27'!K38 -> 0 | AH40: =AE40+AA40 -> 3 | AI40: =AF40+AB40 -> 0 | AJ40: =AG40+AC40 -> 0 | AL40: SALMON Marli | AM40: 0 | AN40: 0 | AO40: 0 | AQ40: ='Apps & Goals 26-27'!L38 -> 1 | AR40: ='Apps & Goals 26-27'!M38 -> 0 | AS40: ='Apps & Goals 26-27'!N38 -> 0 | AT40: =AQ40+AM40 -> 1 | AU40: =AR40+AN40 -> 0 | AV40: =AS40+AO40 -> 0 | AX40: SALMON Marli | AY40: 0 | AZ40: 0 | BA40: 0 | BC40: ='Apps & Goals 26-27'!O38 -> 0 | BD40: ='Apps & Goals 26-27'!P38 -> 0 | BE40: ='Apps & Goals 26-27'!Q38 -> 0 | BF40: =BC40+AY40 -> 0 | BG40: =BD40+AZ40 -> 0 | BH40: =BE40+BA40 -> 0

Sheet Apps & Goals
A1: Arsenal FC squad statistics | Z1: as of
E2: Premier League | H2: Europe | K2: FA Cup | N2: EFL Cup | Q2: Community Shield | T2: Total | Z2: 46307
A3: # | D3: Name | E3: App | F3: Gls | G3: Ast | H3: App | I3: Gls | J3: Ast | K3: App | L3: Gls | M3: Ast | N3: App | O3: Gls | P3: Ast | Q3: App | R3: Gls | S3: Ast | T3: App | U3: Gls | V3: Ast | W3: Loan
A4: 1 | B4: ESP | C4: GK | D4: RAYA David | E4: ='#'!J6 -> 113 | F4: ='#'!K6 -> 0 | G4: ='#'!L6 -> 0 | H4: ='#'!V6 -> 37 | I4: ='#'!W6 -> 0 | J4: ='#'!X6 -> 0 | K4: ='#'!AH6 -> 1 | L4: ='#'!AI6 -> 0 | M4: ='#'!AJ6 -> 0 | N4: ='#'!AT6 -> 3 | O4: ='#'!AU6 -> 0 | P4: ='#'!AV6 -> 0 | Q4: ='#'!BF6 -> 1 | R4: ='#'!BG6 -> 0 | S4: ='#'!BH6 -> 0 | T4: =SUM(E4,H4,K4,N4,Q4) -> 155 | U4: =SUM(F4,I4,L4,O4,R4) -> 0 | V4: =SUM(G4,J4,M4,P4,S4) -> 0
A5: 2 | B5: FRA | C5: DF | D5: SALIBA William | E5: ='#'!J7 -> 131 | F5: ='#'!K7 -> 7 | G5: ='#'!L7 -> 2 | H5: ='#'!V7 -> 37 | I5: ='#'!W7 -> 1 | J5: ='#'!X7 -> 0 | K5: ='#'!AH7 -> 5 | L5: ='#'!AI7 -> 0 | M5: ='#'!AJ7 -> 0 | N5: ='#'!AT7 -> 10 | O5: ='#'!AU7 -> 0 | P5: ='#'!AV7 -> 1 | Q5: ='#'!BF7 -> 1 | R5: ='#'!BG7 -> 0 | S5: ='#'!BH7 -> 0 | T5: =SUM(E5,H5,K5,N5,Q5) -> 184 | U5: =SUM(F5,I5,L5,O5,R5) -> 8 | V5: =SUM(G5,J5,M5,P5,S5) -> 3
A6: 3 | B6: ESP | C6: DF | D6: MOSQUERA Cristhian | E6: ='#'!J8 -> 22 | F6: ='#'!K8 -> 0 | G6: ='#'!L8 -> 0 | H6: ='#'!V8 -> 10 | I6: ='#'!W8 -> 0 | J6: ='#'!X8 -> 0 | K6: ='#'!AH8 -> 3 | L6: ='#'!AI8 -> 0 | M6: ='#'!AJ8 -> 0 | N6: ='#'!AT8 -> 2 | O6: ='#'!AU8 -> 0 | P6: ='#'!AV8 -> 0 | Q6: ='#'!BF8 -> 1 | R6: ='#'!BG8 -> 0 | S6: ='#'!BH8 -> 0 | T6: =SUM(E6,H6,K6,N6,Q6) -> 38 | U6: =SUM(F6,I6,L6,O6,R6) -> 0 | V6: =SUM(G6,J6,M6,P6,S6) -> 0
A7: 4 | B7: ENG | C7: DF | D7: WHITE Ben | E7: ='#'!J9 -> 141 | F7: ='#'!K9 -> 6 | G7: ='#'!L9 -> 14 | H7: ='#'!V9 -> 38 | I7: ='#'!W9 -> 0 | J7: ='#'!X9 -> 2 | K7: ='#'!AH9 -> 6 | L7: ='#'!AI9 -> 0 | M7: ='#'!AJ9 -> 0 | N7: ='#'!AT9 -> 10 | O7: ='#'!AU9 -> 1 | P7: ='#'!AV9 -> 0 | Q7: ='#'!BF9 -> 2 | R7: ='#'!BG9 -> 0 | S7: ='#'!BH9 -> 0 | T7: =SUM(E7,H7,K7,N7,Q7) -> 197 | U7: =SUM(F7,I7,L7,O7,R7) -> 7 | V7: =SUM(G7,J7,M7,P7,S7) -> 16
A8: 5 | B8: ECU | C8: DF | D8: HINCAPIE Piero | E8: ='#'!J10 -> 28 | F8: ='#'!K10 -> 1 | G8: ='#'!L10 -> 2 | H8: ='#'!V10 -> 11 | I8: ='#'!W10 -> 0 | J8: ='#'!X10 -> 0 | K8: ='#'!AH10 -> 1 | L8: ='#'!AI10 -> 0 | M8: ='#'!AJ10 -> 0 | N8: ='#'!AT10 -> 3 | O8: ='#'!AU10 -> 0 | P8: ='#'!AV10 -> 0 | Q8: ='#'!BF10 -> 1 | R8: ='#'!BG10 -> 0 | S8: ='#'!BH10 -> 0 | T8: =SUM(E8,H8,K8,N8,Q8) -> 44 | U8: =SUM(F8,I8,L8,O8,R8) -> 1 | V8: =SUM(G8,J8,M8,P8,S8) -> 2
A9: 6 | B9: BRA | C9: DF | D9: GABRIEL | E9: ='#'!J11 -> 198 | F9: ='#'!K11 -> 20 | G9: ='#'!L11 -> 5 | H9: ='#'!V11 -> 45 | I9: ='#'!W11 -> 3 | J9: ='#'!X11 -> 1 | K9: ='#'!AH11 -> 7 | L9: ='#'!AI11 -> 1 | M9: ='#'!AJ11 -> 0 | N9: ='#'!AT11 -> 18 | O9: ='#'!AU11 -> 0 | P9: ='#'!AV11 -> 0 | Q9: ='#'!BF11 -> 2 | R9: ='#'!BG11 -> 0 | S9: ='#'!BH11 -> 0 | T9: =SUM(E9,H9,K9,N9,Q9) -> 270 | U9: =SUM(F9,I9,L9,O9,R9) -> 24 | V9: =SUM(G9,J9,M9,P9,S9) -> 6
A10: 7 | B10: ENG | C10: FW | D10: SAKA Bukayo | E10: ='#'!J12 -> 232 | F10: ='#'!K12 -> 63 | G10: ='#'!L12 -> 50 | H10: ='#'!V12 -> 55 | I10: ='#'!W12 -> 18 | J10: ='#'!X12 -> 15 | K10: ='#'!AH12 -> 13 | L10: ='#'!AI12 -> 1 | M10: ='#'!AJ12 -> 1 | N10: ='#'!AT12 -> 17 | O10: ='#'!AU12 -> 2 | P10: ='#'!AV12 -> 2 | Q10: ='#'!BF12 -> 3 | R10: ='#'!BG12 -> 0 | S10: ='#'!BH12 -> 2 | T10: =SUM(E10,H10,K10,N10,Q10) -> 320 | U10: =SUM(F10,I10,L10,O10,R10) -> 84 | V10: =SUM(G10,J10,M10,P10,S10) -> 70
A11: 8 | B11: NOR | C11: MF | D11: ODEGAARD Martin | E11: ='#'!J13 -> 182 | F11: ='#'!K13 -> 37 | G11: ='#'!L13 -> 37 | H11: ='#'!V13 -> 42 | I11: ='#'!W13 -> 7 | J11: ='#'!X13 -> 3 | K11: ='#'!AH13 -> 6 | L11: ='#'!AI13 -> 0 | M11: ='#'!AJ13 -> 0 | N11: ='#'!AT13 -> 11 | O11: ='#'!AU13 -> 1 | P11: ='#'!AV13 -> 3 | Q11: ='#'!BF13 -> 2 | R11: ='#'!BG13 -> 1 | S11: ='#'!BH13 -> 0 | T11: =SUM(E11,H11,K11,N11,Q11) -> 243 | U11: =SUM(F11,I11,L11,O11,R11) -> 46 | V11: =SUM(G11,J11,M11,P11,S11) -> 43
A12: 10 | B12: ENG | C12: MF | D12: EZE Eberechi | E12: ='#'!J14 -> 36 | F12: ='#'!K14 -> 7 | G12: ='#'!L14 -> 2 | H12: ='#'!V14 -> 14 | I12: ='#'!W14 -> 1 | J12: ='#'!X14 -> 1 | K12: ='#'!AH14 -> 3 | L12: ='#'!AI14 -> 1 | M12: ='#'!AJ14 -> 2 | N12: ='#'!AT14 -> 5 | O12: ='#'!AU14 -> 1 | P12: ='#'!AV14 -> 1 | Q12: ='#'!BF14 -> 1 | R12: ='#'!BG14 -> 0 | S12: ='#'!BH14 -> 0 | T12: =SUM(E12,H12,K12,N12,Q12) -> 59 | U12: =SUM(F12,I12,L12,O12,R12) -> 10 | V12: =SUM(G12,J12,M12,P12,S12) -> 6
A13: 12 | B13: NED | C13: DF | D13: TIMBER Jurrien | E13: ='#'!J15 -> 65 | F13: ='#'!K15 -> 4 | G13: ='#'!L15 -> 8 | H13: ='#'!V15 -> 21 | I13: ='#'!W15 -> 2 | J13: ='#'!X15 -> 2 | K13: ='#'!AH15 -> 3 | L13: ='#'!AI15 -> 0 | M13: ='#'!AJ15 -> 0 | N13: ='#'!AT15 -> 8 | O13: ='#'!AU15 -> 0 | P13: ='#'!AV15 -> 0 | Q13: ='#'!BF15 -> 1 | R13: ='#'!BG15 -> 0 | S13: ='#'!BH15 -> 0 | T13: =SUM(E13,H13,K13,N13,Q13) -> 98 | U13: =SUM(F13,I13,L13,O13,R13) -> 6 | V13: =SUM(G13,J13,M13,P13,S13) -> 10
A14: 13 | B14: ESP | C14: GK | D14: KEPA Arrizabalaga | E14: ='#'!J16 -> 1 | F14: ='#'!K16 -> 0 | G14: ='#'!L16 -> 0 | H14: ='#'!V16 -> 1 | I14: ='#'!W16 -> 0 | J14: ='#'!X16 -> 0 | K14: ='#'!AH16 -> 4 | L14: ='#'!AI16 -> 0 | M14: ='#'!AJ16 -> 0 | N14: ='#'!AT16 -> 7 | O14: ='#'!AU16 -> 0 | P14: ='#'!AV16 -> 0 | Q14: ='#'!BF16 -> 0 | R14: ='#'!BG16 -> 0 | S14: ='#'!BH16 -> 0 | T14: =SUM(E14,H14,K14,N14,Q14) -> 13 | U14: =SUM(F14,I14,L14,O14,R14) -> 0 | V14: =SUM(G14,J14,M14,P14,S14) -> 0
A15: 14 | B15: SWE | C15: FW | D15: GYOKERES Viktor | E15: ='#'!J17 -> 39 | F15: ='#'!K17 -> 14 | G15: ='#'!L17 -> 1 | H15: ='#'!V17 -> 14 | I15: ='#'!W17 -> 5 | J15: ='#'!X17 -> 1 | K15: ='#'!AH17 -> 2 | L15: ='#'!AI17 -> 1 | M15: ='#'!AJ17 -> 0 | N15: ='#'!AT17 -> 5 | O15: ='#'!AU17 -> 1 | P15: ='#'!AV17 -> 1 | Q15: ='#'!BF17 -> 1 | R15: ='#'!BG17 -> 0 | S15: ='#'!BH17 -> 0 | T15: =SUM(E15,H15,K15,N15,Q15) -> 61 | U15: =SUM(F15,I15,L15,O15,R15) -> 21 | V15: =SUM(G15,J15,M15,P15,S15) -> 3
... A18: 20 | B18: ENG | C18: FW | D18: MADUEKE Nuno | E18: ='#'!J20 -> 29 | F18: ='#'!K20 -> 3 | G18: ='#'!L20 -> 1 | H18: ='#'!V20 -> 10 | I18: ='#'!W20 -> 3 | J18: ='#'!X20 -> 0 | K18: ='#'!AH20 -> 4 | L18: ='#'!AI20 -> 2 | M18: ='#'!AJ20 -> 2 | N18: ='#'!AT20 -> 4 | O18: ='#'!AU20 -> 1 | P18: ='#'!AV20 -> 0 | Q18: ='#'!BF20 -> 1 | R18: ='#'!BG20 -> 0 | S18: ='#'!BH20 -> 0 | T18: =SUM(E18,H18,K18,N18,Q18) -> 48 | U18: =SUM(F18,I18,L18,O18,R18) -> 9 | V18: =SUM(G18,J18,M18,P18,S18) -> 3
A19: 22 | B19: ENG | C19: MF | D19: NWANERI Ethan | E19: ='#'!J21 -> 34 | F19: ='#'!K21 -> 4 | G19: ='#'!L21 -> 2 | H19: ='#'!V21 -> 10 | I19: ='#'!W21 -> 2 | J19: ='#'!X21 -> 0 | K19: ='#'!AH21 -> 1 | L19: ='#'!AI21 -> 0 | M19: ='#'!AJ21 -> 0 | N19: ='#'!AT21 -> 6 | O19: ='#'!AU21 -> 4 | P19: ='#'!AV21 -> 0 | Q19: ='#'!BF21 -> 0 | R19: ='#'!BG21 -> 0 | S19: ='#'!BH21 -> 0 | T19: =SUM(E19,H19,K19,N19,Q19) -> 51 | U19: =SUM(F19,I19,L19,O19,R19) -> 10 | V19: =SUM(G19,J19,M19,P19,S19) -> 2 | W19: Y
A20: 23 | B20: ESP | C20: MF | D20: MERINO Mikel | E20: ='#'!J22 -> 56 | F20: ='#'!K22 -> 11 | G20: ='#'!L22 -> 5 | H20: ='#'!V22 -> 20 | I20: ='#'!W22 -> 4 | J20: ='#'!X22 -> 3 | K20: ='#'!AH22 -> 2 | L20: ='#'!AI22 -> 0 | M20: ='#'!AJ22 -> 0 | N20: ='#'!AT22 -> 8 | O20: ='#'!AU22 -> 1 | P20: ='#'!AV22 -> 0 | Q20: ='#'!BF22 -> 0 | R20: ='#'!BG22 -> 0 | S20: ='#'!BH22 -> 0 | T20: =SUM(E20,H20,K20,N20,Q20) -> 86 | U20: =SUM(F20,I20,L20,O20,R20) -> 16 | V20: =SUM(G20,J20,M20,P20,S20) -> 8
A21: 29 | B21: GER | C21: FW | D21: HAVERTZ Kai | E21: ='#'!J23 -> 78 | F21: ='#'!K23 -> 26 | G21: ='#'!L23 -> 13 | H21: ='#'!V23 -> 25 | I21: ='#'!W23 -> 9 | J21: ='#'!X23 -> 2 | K21: ='#'!AH23 -> 5 | L21: ='#'!AI23 -> 0 | M21: ='#'!AJ23 -> 1 | N21: ='#'!AT23 -> 9 | O21: ='#'!AU23 -> 3 | P21: ='#'!AV23 -> 0 | Q21: ='#'!BF23 -> 2 | R21: ='#'!BG23 -> 1 | S21: ='#'!BH23 -> 0 | T21: =SUM(E21,H21,K21,N21,Q21) -> 119 | U21: =SUM(F21,I21,L21,O21,R21) -> 39 | V21: =SUM(G21,J21,M21,P21,S21) -> 16
A22: 30 | B22: FRA | C22: GK | D22: MESLIER Illan | E22: ='#'!J24 -> 0 | F22: ='#'!K24 -> 0 | G22: ='#'!L24 -> 0 | H22: ='#'!V24 -> 0 | I22: ='#'!W24 -> 0 | J22: ='#'!X24 -> 0 | K22: ='#'!AH24 -> 0 | L22: ='#'!AI24 -> 0 | M22: ='#'!AJ24 -> 0 | N22: ='#'!AT24 -> 0 | O22: ='#'!AU24 -> 0 | P22: ='#'!AV24 -> 0 | Q22: ='#'!BF24 -> 0 | R22: ='#'!BG24 -> 0 | S22: ='#'!BH24 -> 0 | T22: =SUM(E22,H22,K22,N22,Q22) -> 0 | U22: =SUM(F22,I22,L22,O22,R22) -> 0 | V22: =SUM(G22,J22,M22,P22,S22) -> 0
A23: 33 | B23: ITA | C23: DF | D23: CALAFIORI Riccardo | E23: ='#'!J25 -> 51 | F23: ='#'!K25 -> 4 | G23: ='#'!L25 -> 5 | H23: ='#'!V25 -> 14 | I23: ='#'!W25 -> 1 | J23: ='#'!X25 -> 2 | K23: ='#'!AH25 -> 2 | L23: ='#'!AI25 -> 0 | M23: ='#'!AJ25 -> 0 | N23: ='#'!AT25 -> 4 | O23: ='#'!AU25 -> 0 | P23: ='#'!AV25 -> 0 | Q23: ='#'!BF25 -> 1 | R23: ='#'!BG25 -> 1 | S23: ='#'!BH25 -> 0 | T23: =SUM(E23,H23,K23,N23,Q23) -> 72 | U23: =SUM(F23,I23,L23,O23,R23) -> 6 | V23: =SUM(G23,J23,M23,P23,S23) -> 7
A24: 35 | B24: ENG | C24: GK | D24: SETFORD Tommy | E24: ='#'!J26 -> 0 | F24: ='#'!K26 -> 0 | G24: ='#'!L26 -> 0 | H24: ='#'!V26 -> 0 | I24: ='#'!W26 -> 0 | J24: ='#'!X26 -> 0 | K24: ='#'!AH26 -> 1 | L24: ='#'!AI26 -> 0 | M24: ='#'!AJ26 -> 0 | N24: ='#'!AT26 -> 1 | O24: ='#'!AU26 -> 0 | P24: ='#'!AV26 -> 0 | Q24: ='#'!BF26 -> 0 | R24: ='#'!BG26 -> 0 | S24: ='#'!BH26 -> 0 | T24: =SUM(E24,H24,K24,N24,Q24) -> 2 | U24: =SUM(F24,I24,L24,O24,R24) -> 0 | V24: =SUM(G24,J24,M24,P24,S24) -> 0 | W24: Y
A25: 36 | B25: ESP | C25: MF | D25: ZUBIMENDI Martin | E25: ='#'!J27 -> 43 | F25: ='#'!K27 -> 5 | G25: ='#'!L27 -> 1 | H25: ='#'!V27 -> 14 | I25: ='#'!W27 -> 0 | J25: ='#'!X27 -> 2 | K25: ='#'!AH27 -> 3 | L25: ='#'!AI27 -> 0 | M25: ='#'!AJ27 -> 0 | N25: ='#'!AT27 -> 4 | O25: ='#'!AU27 -> 1 | P25: ='#'!AV27 -> 1 | Q25: ='#'!BF27 -> 1 | R25: ='#'!BG27 -> 0 | S25: ='#'!BH27 -> 0 | T25: =SUM(E25,H25,K25,N25,Q25) -> 65 | U25: =SUM(F25,I25,L25,O25,R25) -> 6 | V25: =SUM(G25,J25,M25,P25,S25) -> 4
A26: 39 | B26: BRA | C26: MF | D26: GUIMARES Bruno | E26: ='#'!J28 -> 4 | F26: ='#'!K28 -> 2 | G26: ='#'!L28 -> 0 | H26: ='#'!V28 -> 1 | I26: ='#'!W28 -> 0 | J26: ='#'!X28 -> 0 | K26: ='#'!AH28 -> 0 | L26: ='#'!AI28 -> 0 | M26: ='#'!AJ28 -> 0 | N26: ='#'!AT28 -> 1 | O26: ='#'!AU28 -> 0 | P26: ='#'!AV28 -> 0 | Q26: ='#'!BF28 -> 1 | R26: ='#'!BG28 -> 0 | S26: ='#'!BH28 -> 0 | T26: =SUM(E26,H26,K26,N26,Q26) -> 7 | U26: =SUM(F26,I26,L26,O26,R26) -> 2 | V26: =SUM(G26,J26,M26,P26,S26) -> 0
A27: 40 | B27: ENG | C27: DF | D27: DIXON Jaden | E27: ='#'!J29 -> 0 | F27: ='#'!K29 -> 0 | G27: ='#'!L29 -> 0 | H27: ='#'!V29 -> 0 | I27: ='#'!W29 -> 0 | J27: ='#'!X29 -> 0 | K27: ='#'!AH29 -> 1 | L27: ='#'!AI29 -> 0 | M27: ='#'!AJ29 -> 0 | N27: ='#'!AT29 -> 0 | O27: ='#'!AU29 -> 0 | P27: ='#'!AV29 -> 0 | Q27: ='#'!BF29 -> 0 | R27: ='#'!BG29 -> 0 | S27: ='#'!BH29 -> 0 | T27: =SUM(E27,H27,K27,N27,Q27) -> 1 | U27: =SUM(F27,I27,L27,O27,R27) -> 0 | V27: =SUM(G27,J27,M27,P27,S27) -> 0
A28: 41 | B28: ENG | C28: MF | D28: RICE Declan | E28: ='#'!J30 -> 115 | F28: ='#'!K30 -> 15 | G28: ='#'!L30 -> 23 | H28: ='#'!V30 -> 37 | I28: ='#'!W30 -> 5 | J28: ='#'!X30 -> 5 | K28: ='#'!AH30 -> 2 | L28: ='#'!AI30 -> 0 | M28: ='#'!AJ30 -> 0 | N28: ='#'!AT30 -> 10 | O28: ='#'!AU30 -> 1 | P28: ='#'!AV30 -> 3 | Q28: ='#'!BF30 -> 2 | R28: ='#'!BG30 -> 0 | S28: ='#'!BH30 -> 0 | T28: =SUM(E28,H28,K28,N28,Q28) -> 166 | U28: =SUM(F28,I28,L28,O28,R28) -> 21 | V28: =SUM(G28,J28,M28,P28,S28) -> 31
A29: 43 | B29: ENG | C29: FW | D29: HARRIMAN-ANNOUS Andre | E29: ='#'!J31 -> 0 | F29: ='#'!K31 -> 0 | G29: ='#'!L31 -> 0 | H29: ='#'!V31 -> 1 | I29: ='#'!W31 -> 0 | J29: ='#'!X31 -> 0 | K29: ='#'!AH31 -> 0 | L29: ='#'!AI31 -> 0 | M29: ='#'!AJ31 -> 0 | N29: ='#'!AT31 -> 1 | O29: ='#'!AU31 -> 0 | P29: ='#'!AV31 -> 0 | Q29: ='#'!BF31 -> 0 | R29: ='#'!BG31 -> 0 | S29: ='#'!BH31 -> 0 | T29: =SUM(E29,H29,K29,N29,Q29) -> 2 | U29: =SUM(F29,I29,L29,O29,R29) -> 0 | V29: =SUM(G29,J29,M29,P29,S29) -> 0
A30: 44 | B30: ENG | C30: MF | D30: IBRAHIM Ife | E30: ='#'!J32 -> 0 | F30: ='#'!K32 -> 0 | G30: ='#'!L32 -> 0 | H30: ='#'!V32 -> 1 | I30: ='#'!W32 -> 0 | J30: ='#'!X32 -> 0 | K30: ='#'!AH32 -> 0 | L30: ='#'!AI32 -> 0 | M30: ='#'!AJ32 -> 0 | N30: ='#'!AT32 -> 1 | O30: ='#'!AU32 -> 0 | P30: ='#'!AV32 -> 0 | Q30: ='#'!BF32 -> 0 | R30: ='#'!BG32 -> 0 | S30: ='#'!BH32 -> 0 | T30: =SUM(E30,H30,K30,N30,Q30) -> 2 | U30: =SUM(F30,I30,L30,O30,R30) -> 0 | V30: =SUM(G30,J30,M30,P30,S30) -> 0
A31: 45 | B31: ENG | C31: MF | D31: JULIENNE Theo | E31: ='#'!J33 -> 0 | F31: ='#'!K33 -> 0 | G31: ='#'!L33 -> 0 | H31: ='#'!V33 -> 0 | I31: ='#'!W33 -> 0 | J31: ='#'!X33 -> 0 | K31: ='#'!AH33 -> 0 | L31: ='#'!AI33 -> 0 | M31: ='#'!AJ33 -> 0 | N31: ='#'!AT33 -> 1 | O31: ='#'!AU33 -> 0 | P31: ='#'!AV33 -> 0 | Q31: ='#'!BF33 -> 0 | R31: ='#'!BG33 -> 0 | S31: ='#'!BH33 -> 0 | T31: =SUM(E31,H31,K31,N31,Q31) -> 1 | U31: =SUM(F31,I31,L31,O31,R31) -> 0 | V31: =SUM(G31,J31,M31,P31,S31) -> 0
A32: 46 | B32: NED | C32: FW | D32: KABIA Ismeal | E32: ='#'!J34 -> 0 | F32: ='#'!K34 -> 0 | G32: ='#'!L34 -> 0 | H32: ='#'!V34 -> 0 | I32: ='#'!W34 -> 0 | J32: ='#'!X34 -> 0 | K32: ='#'!AH34 -> 0 | L32: ='#'!AI34 -> 0 | M32: ='#'!AJ34 -> 0 | N32: ='#'!AT34 -> 1 | O32: ='#'!AU34 -> 0 | P32: ='#'!AV34 -> 0 | Q32: ='#'!BF34 -> 0 | R32: ='#'!BG34 -> 0 | S32: ='#'!BH34 -> 0 | T32: =SUM(E32,H32,K32,N32,Q32) -> 1 | U32: =SUM(F32,I32,L32,O32,R32) -> 0 | V32: =SUM(G32,J32,M32,P32,S32) -> 0 | W32: Y
A33: 49 | B33: ENG | C33: DF | D33: LEWIS-SKELLY Myles | E33: ='#'!J35 -> 48 | F33: ='#'!K35 -> 1 | G33: ='#'!L35 -> 0 | H33: ='#'!V35 -> 20 | I33: ='#'!W35 -> 0 | J33: ='#'!X35 -> 3 | K33: ='#'!AH35 -> 4 | L33: ='#'!AI35 -> 0 | M33: ='#'!AJ35 -> 0 | N33: ='#'!AT35 -> 9 | O33: ='#'!AU35 -> 0 | P33: ='#'!AV35 -> 2 | Q33: ='#'!BF35 -> 1 | R33: ='#'!BG35 -> 0 | S33: ='#'!BH35 -> 1 | T33: =SUM(E33,H33,K33,N33,Q33) -> 82 | U33: =SUM(F33,I33,L33,O33,R33) -> 1 | V33: =SUM(G33,J33,M33,P33,S33) -> 6
A34: 53 | B34: ENG | C34: FW | D34: SAGOE JR Charles | E34: ='#'!J36 -> 0 | F34: ='#'!K36 -> 0 | G34: ='#'!L36 -> 0 | H34: ='#'!V36 -> 0 | I34: ='#'!W36 -> 0 | J34: ='#'!X36 -> 0 | K34: ='#'!AH36 -> 0 | L34: ='#'!AI36 -> 0 | M34: ='#'!AJ36 -> 0 | N34: ='#'!AT36 -> 1 | O34: ='#'!AU36 -> 0 | P34: ='#'!AV36 -> 0 | Q34: ='#'!BF36 -> 0 | R34: ='#'!BG36 -> 0 | S34: ='#'!BH36 -> 0 | T34: =SUM(E34,H34,K34,N34,Q34) -> 1 | U34: =SUM(F34,I34,L34,O34,R34) -> 0 | V34: =SUM(G34,J34,M34,P34,S34) -> 0 | W34: Y
A35: 55 | B35: ENG | C35: GK | D35: PORTER Jack | E35: ='#'!J37 -> 0 | F35: ='#'!K37 -> 0 | G35: ='#'!L37 -> 0 | H35: ='#'!V37 -> 0 | I35: ='#'!W37 -> 0 | J35: ='#'!X37 -> 0 | K35: ='#'!AH37 -> 0 | L35: ='#'!AI37 -> 0 | M35: ='#'!AJ37 -> 0 | N35: ='#'!AT37 -> 1 | O35: ='#'!AU37 -> 0 | P35: ='#'!AV37 -> 0 | Q35: ='#'!BF37 -> 0 | R35: ='#'!BG37 -> 0 | S35: ='#'!BH37 -> 0 | T35: =SUM(E35,H35,K35,N35,Q35) -> 1 | U35: =SUM(F35,I35,L35,O35,R35) -> 0 | V35: =SUM(G35,J35,M35,P35,S35) -> 0
A36: 56 | B36: ENG | C36: FW | D36: DOWMAN Max | E36: ='#'!J38 -> 7 | F36: ='#'!K38 -> 1 | G36: ='#'!L38 -> 0 | H36: ='#'!V38 -> 3 | I36: ='#'!W38 -> 0 | J36: ='#'!X38 -> 0 | K36: ='#'!AH38 -> 2 | L36: ='#'!AI38 -> 0 | M36: ='#'!AJ38 -> 0 | N36: ='#'!AT38 -> 3 | O36: ='#'!AU38 -> 2 | P36: ='#'!AV38 -> 0 | Q36: ='#'!BF38 -> 0 | R36: ='#'!BG38 -> 0 | S36: ='#'!BH38 -> 0 | T36: =SUM(E36,H36,K36,N36,Q36) -> 15 | U36: =SUM(F36,I36,L36,O36,R36) -> 3 | V36: =SUM(G36,J36,M36,P36,S36) -> 0
A37: 71 | B37: ENG | C37: FW | D37: BAILEY-JOSEPH Brando | E37: ='#'!J39 -> 0 | F37: ='#'!K39 -> 0 | G37: ='#'!L39 -> 0 | H37: ='#'!V39 -> 1 | I37: ='#'!W39 -> 0 | J37: ='#'!X39 -> 0 | K37: ='#'!AH39 -> 0 | L37: ='#'!AI39 -> 0 | M37: ='#'!AJ39 -> 0 | N37: ='#'!AT39 -> 0 | O37: ='#'!AU39 -> 0 | P37: ='#'!AV39 -> 0 | Q37: ='#'!BF39 -> 0 | R37: ='#'!BG39 -> 0 | S37: ='#'!BH39 -> 0 | T37: =SUM(E37,H37,K37,N37,Q37) -> 1 | U37: =SUM(F37,I37,L37,O37,R37) -> 0 | V37: =SUM(G37,J37,M37,P37,S37) -> 0
A38: 89 | B38: ENG | C38: DF | D38: SALMON Marli | E38: ='#'!J40 -> 0 | F38: ='#'!K40 -> 0 | G38: ='#'!L40 -> 0 | H38: ='#'!V40 -> 1 | I38: ='#'!W40 -> 0 | J38: ='#'!X40 -> 0 | K38: ='#'!AH40 -> 3 | L38: ='#'!AI40 -> 0 | M38: ='#'!AJ40 -> 0 | N38: ='#'!AT40 -> 1 | O38: ='#'!AU40 -> 0 | P38: ='#'!AV40 -> 0 | Q38: ='#'!BF40 -> 0 | R38: ='#'!BG40 -> 0 | S38: ='#'!BH40 -> 0 | T38: =SUM(E38,H38,K38,N38,Q38) -> 5 | U38: =SUM(F38,I38,L38,O38,R38) -> 0 | V38: =SUM(G38,J38,M38,P38,S38) -> 0
F40: `

Sheet Apps & Goals 16-17
A1: Arsenal FC squad statistics | D1: Update:
D2: Premier League | F2: Champions League | H2: FA Cup | J2: EFL Cup | L2: Community Shield | N2: Total
A3: # | B3: Name | C3: S | D3: Apps | E3: Goals | F3: Apps | G3: Goals | H3: Apps | I3: Goals | J3: Apps | K3: Goals | L3: Apps | M3: Goals | N3: Apps | O3: Goals
A4: 1 | B4: SZCZĘSNY Wojciech | C4: 7 | D4: 0 | E4: 0 | F4: 0 | G4: 0 | H4: 0 | I4: 0 | J4: 0 | K4: 0 | L4: 0 | M4: 0 | N4: 0 | O4: 0
A5: 2 | B5: DEBUCHY Mathieu | C5: 2 | D5: 1 | E5: 0 | F5: 0 | G5: 0 | H5: 0 | I5: 0 | J5: 0 | K5: 0 | L5: 0 | M5: 0 | N5: 1 | O5: 0
A6: 3 | B6: GIBBS Kieran | C6: 9 | D6: 11 | E6: 0 | F6: 6 | G6: 0 | H6: 2 | I6: 0 | J6: 3 | K6: 0 | L6: 0 | M6: 0 | N6: 22 | O6: 0
A7: 4 | B7: MERTESACKER Per | C7: 5 | D7: 1 | E7: 0 | F7: 0 | G7: 0 | H7: 1 | I7: 0 | J7: 0 | K7: 0 | L7: 0 | M7: 0 | N7: 2 | O7: 0
A8: 5 | B8: Paulista GABRIEL | C8: 2 | D8: 19 | E8: 0 | F8: 2 | G8: 0 | H8: 3 | I8: 0 | J8: 3 | K8: 0 | L8: 0 | M8: 0 | N8: 27 | O8: 0
A9: 6 | B9: KOSCIELNY Laurent | C9: 6 | D9: 33 | E9: 2 | F9: 8 | G9: 0 | H9: 2 | I9: 0 | J9: 0 | K9: 0 | L9: 0 | M9: 0 | N9: 43 | O9: 2
A10: 7 | B10: SANCHEZ Alexis | C10: 2 | D10: 38 | E10: 24 | F10: 8 | G10: 3 | H10: 5 | I10: 3 | J10: 0 | K10: 0 | L10: 0 | M10: 0 | N10: 51 | O10: 30
A11: 8 | B11: RAMSEY Aaron | C11: 8 | D11: 23 | E11: 1 | F11: 4 | G11: 0 | H11: 4 | I11: 3 | J11: 1 | K11: 0 | L11: 0 | M11: 0 | N11: 32 | O11: 4
A12: 9 | B12: PEREZ Lucas | C12: 1 | D12: 12 | E12: 1 | F12: 3 | G12: 3 | H12: 4 | I12: 1 | J12: 3 | K12: 2 | L12: 0 | M12: 0 | N12: 22 | O12: 7
A13: 10 | B13: WILSHERE Jack | C13: 8 | D13: 2 | E13: 0 | F13: 0 | G13: 0 | H13: 0 | I13: 0 | J13: 0 | K13: 0 | L13: 0 | M13: 0 | N13: 2 | O13: 0
A14: 11 | B14: OZIL Mesut | C14: 3 | D14: 33 | E14: 8 | F14: 8 | G14: 4 | H14: 3 | I14: 0 | J14: 0 | K14: 0 | L14: 0 | M14: 0 | N14: 44 | O14: 12
A15: 12 | B15: GIROUD Olivier | C15: 4 | D15: 29 | E15: 12 | F15: 6 | G15: 2 | H15: 4 | I15: 2 | J15: 1 | K15: 0 | L15: 0 | M15: 0 | N15: 40 | O15: 16
... A43: 73 | B43: O'CONNOR Stefan | C43: 2 | D43: 0 | E43: 0 | F43: 0 | G43: 0 | H43: 0 | I43: 0 | J43: 0 | K43: 0 | L43: 0 | M43: 0 | N43: 0 | O43: 0

Sheet Apps & Goals 17-18
A1: Arsenal FC squad statistics
D2: Premier League | F2: Europa League | H2: FA Cup | J2: EFL Cup | L2: Community Shield | N2: Total
A3: # | B3: Name | C3: S | D3: Apps | E3: Goals | F3: Apps | G3: Goals | H3: Apps | I3: Goals | J3: Apps | K3: Goals | L3: Apps | M3: Goals | N3: Apps | O3: Goals
A4: 4 | B4: MERTESACKER Per | C4: 8 | D4: 6 | E4: 1 | F4: 3 | G4: 0 | H4: 1 | I4: 1 | J4: 1 | K4: 0 | L4: 1 | M4: 0 | N4: 12 | O4: 2
A5: 6 | B5: KOSCIELNY Laurent | C5: 8 | D5: 25 | E5: 2 | F5: 4 | G5: 0 | H5: 0 | I5: 0 | J5: 2 | K5: 0 | L5: 0 | M5: 0 | N5: 31 | O5: 2
A6: 7 | B6: MKHITARYAN Henrikh | C6: 1 | D6: 11 | E6: 2 | F6: 5 | G6: 1 | H6: 0 | I6: 0 | J6: 0 | K6: 0 | L6: 0 | M6: 0 | N6: 16 | O6: 3
A7: 8 | B7: RAMSEY Aaron | C7: 10 | D7: 25 | E7: 7 | F7: 4 | G7: 4 | H7: 0 | I7: 0 | J7: 2 | K7: 0 | L7: 0 | M7: 0 | N7: 31 | O7: 11
A8: 9 | B8: LACAZETTE Alexandre | C8: 1 | D8: 31 | E8: 14 | F8: 2 | G8: 2 | H8: 0 | I8: 0 | J8: 2 | K8: 0 | L8: 1 | M8: 0 | N8: 36 | O8: 16
A9: 10 | B9: WILSHERE Jack | C9: 10 | D9: 20 | E9: 1 | F9: 11 | G9: 1 | H9: 0 | I9: 0 | J9: 5 | K9: 0 | L9: 0 | M9: 0 | N9: 36 | O9: 2
A10: 11 | B10: OZIL Mesut | C10: 5 | D10: 26 | E10: 4 | F10: 5 | G10: 1 | H10: 0 | I10: 0 | J10: 2 | K10: 0 | L10: 0 | M10: 0 | N10: 33 | O10: 5
A11: 13 | B11: OSPINA David | C11: 4 | D11: 5 | E11: 0 | F11: 8 | G11: 0 | H11: 1 | I11: 0 | J11: 5 | K11: 0 | L11: 0 | M11: 0 | N11: 19 | O11: 0
A12: 14 | B12: AUBAMEYANG Pierre-Emerick | C12: 1 | D12: 13 | E12: 10 | F12: 0 | G12: 0 | H12: 0 | I12: 0 | J12: 1 | K12: 0 | L12: 0 | M12: 0 | N12: 14 | O12: 10
A13: 16 | B13: HOLDING Rob | C13: 3 | D13: 12 | E13: 0 | F13: 8 | G13: 1 | H13: 1 | I13: 0 | J13: 4 | K13: 0 | L13: 1 | M13: 0 | N13: 26 | O13: 1
A14: 17 | B14: IWOBI Alex | C14: 5 | D14: 26 | E14: 3 | F14: 6 | G14: 0 | H14: 1 | I14: 0 | J14: 5 | K14: 0 | L14: 1 | M14: 0 | N14: 39 | O14: 3
A15: 18 | B15: MONREAL Nacho | C15: 6 | D15: 28 | E15: 5 | F15: 5 | G15: 1 | H15: 0 | I15: 0 | J15: 2 | K15: 0 | L15: 1 | M15: 0 | N15: 36 | O15: 6
... A24: 27 | B24: MAVROPANOS Konstantinos | C24: 1 | D24: 3 | E24: 0 | F24: 0 | G24: 0 | H24: 0 | I24: 0 | J24: 0 | K24: 0 | L24: 0 | M24: 0 | N24: 3 | O24: 0
A25: - | B25: CAMPBELL Joel | C25: 7 | D25: 0 | E25: 0 | F25: 0 | G25: 0 | H25: 0 | I25: 0 | J25: 0 | K25: 0 | L25: 0 | M25: 0 | N25: 0 | O25: 0
A26: 28 | B26: PEREZ Lucas | C26: 4 | D26: 0 | E26: 0 | F26: 0 | G26: 0 | H26: 0 | I26: 0 | J26: 0 | K26: 0 | L26: 0 | M26: 0 | N26: 0 | O26: 0
A27: 29 | B27: XHAKA Granit | C27: 3 | D27: 38 | E27: 1 | F27: 4 | G27: 1 | H27: 0 | I27: 0 | J27: 3 | K27: 1 | L27: 1 | M27: 0 | N27: 46 | O27: 3
A28: 30 | B28: MAITLAND-NILES Ainsley | C28: 5 | D28: 16 | E28: 0 | F28: 9 | G28: 0 | H28: 1 | I28: 0 | J28: 3 | K28: 0 | L28: 0 | M28: 0 | N28: 29 | O28: 0
A29: 31 | B29: KOLASINAC Sead | C29: 1 | D29: 26 | E29: 2 | F29: 5 | G29: 2 | H29: 0 | I29: 0 | J29: 3 | K29: 0 | L29: 1 | M29: 1 | N29: 35 | O29: 5
A30: 32 | B30: AKPOM Chuba | C30: 5 | D30: 0 | E30: 0 | F30: 0 | G30: 0 | H30: 1 | I30: 0 | J30: 1 | K30: 0 | L30: 0 | M30: 0 | N30: 2 | O30: 0
A31: 33 | B31: CECH Petr | C31: 3 | D31: 34 | E31: 0 | F31: 3 | G31: 0 | H31: 0 | I31: 0 | J31: 0 | K31: 0 | L31: 1 | M31: 0 | N31: 38 | O31: 0
A32: 35 | B32: ELNENY Mohamed | C32: 3 | D32: 13 | E32: 0 | F32: 12 | G32: 1 | H32: 1 | I32: 0 | J32: 5 | K32: 0 | L32: 1 | M32: 0 | N32: 32 | O32: 1
A33: 37 | B33: BIELIK Krystian | C33: 4 | D33: 0 | E33: 0 | F33: 0 | G33: 0 | H33: 0 | I33: 0 | J33: 0 | K33: 0 | L33: 0 | M33: 0 | N33: 0 | O33: 0
A34: 40 | B34: ZELALEM Gedion | C34: 5 | D34: 0 | E34: 0 | F34: 0 | G34: 0 | H34: 0 | I34: 0 | J34: 0 | K34: 0 | L34: 0 | M34: 0 | N34: 0 | O34: 0
A35: 43 | B35: DA SILVA Joshua | C35: 1 | D35: 0 | E35: 0 | F35: 0 | G35: 0 | H35: 0 | I35: 0 | J35: 3 | K35: 0 | L35: 0 | M35: 0 | N35: 3 | O35: 0
A36: 54 | B36: MACEY Matt | C36: 1 | D36: 0 | E36: 0 | F36: 0 | G36: 0 | H36: 0 | I36: 0 | J36: 1 | K36: 0 | L36: 0 | M36: 0 | N36: 1 | O36: 0
A37: 58 | B37: MCGUANE Marcus | C37: 1 | D37: 0 | E37: 0 | F37: 3 | G37: 0 | H37: 0 | I37: 0 | J37: 0 | K37: 0 | L37: 0 | M37: 0 | N37: 3 | O37: 0
... A41: 69 | B41: WILLOCK Joe | C41: 1 | D41: 2 | E41: 0 | F41: 5 | G41: 0 | H41: 1 | I41: 0 | J41: 3 | K41: 0 | L41: 0 | M41: 0 | N41: 11 | O41: 0

Sheet Apps & Goals 18-19
A1: Arsenal FC squad statistics
D2: Premier League | F2: Europa League | H2: FA Cup | J2: EFL Cup | L2: Community Shield | N2: Total
A3: # | B3: Name | C3: S | D3: Apps | E3: Goals | F3: Apps | G3: Goals | H3: Apps | I3: Goals | J3: Apps | K3: Goals | L3: Apps | M3: Goals | N3: Apps | O3: Goals
A4: 1 | B4: CECH Petr | C4: 4 | D4: 7 | E4: 0 | F4: 11 | G4: 0 | H4: 2 | I4: 0 | J4: 2 | K4: 0 | L4: 0 | M4: 0 | N4: 22 | O4: 0
A5: 2 | B5: BELLERIN Hector | C5: 6 | D5: 19 | E5: 0 | F5: 0 | G5: 0 | H5: 0 | I5: 0 | J5: 0 | K5: 0 | L5: 0 | M5: 0 | N5: 19 | O5: 0
A6: 4 | B6: ELNENY Mohamed | C6: 4 | D6: 8 | E6: 0 | F6: 7 | G6: 0 | H6: 1 | I6: 0 | J6: 1 | K6: 0 | L6: 0 | M6: 0 | N6: 17 | O6: 0
A7: 5 | B7: PAPASTATHOPULOS Sokratis | C7: 1 | D7: 25 | E7: 1 | F7: 12 | G7: 2 | H7: 2 | I7: 0 | J7: 1 | K7: 0 | L7: 0 | M7: 0 | N7: 40 | O7: 3
A8: 6 | B8: KOSCIELNY Laurent | C8: 9 | D8: 16 | E8: 3 | F8: 10 | G8: 0 | H8: 1 | I8: 0 | J8: 1 | K8: 0 | L8: 0 | M8: 0 | N8: 28 | O8: 3
A9: 7 | B9: MKHITARYAN Henrikh | C9: 2 | D9: 24 | E9: 6 | F9: 11 | G9: 0 | H9: 0 | I9: 0 | J9: 3 | K9: 0 | L9: 0 | M9: 0 | N9: 38 | O9: 6
A10: 8 | B10: RAMSEY Aaron | C10: 11 | D10: 29 | E10: 4 | F10: 7 | G10: 2 | H10: 2 | I10: 0 | J10: 3 | K10: 0 | L10: 0 | M10: 0 | N10: 41 | O10: 6
A11: 9 | B11: LACAZETTE Alexandre | C11: 2 | D11: 35 | E11: 13 | F11: 10 | G11: 5 | H11: 2 | I11: 0 | J11: 2 | K11: 1 | L11: 0 | M11: 0 | N11: 49 | O11: 19
A12: 10 | B12: OZIL Mesut | C12: 6 | D12: 23 | E12: 5 | F12: 10 | G12: 1 | H12: 1 | I12: 0 | J12: 0 | K12: 0 | L12: 0 | M12: 0 | N12: 34 | O12: 6
A13: 11 | B13: TORREIRA Lucas | C13: 1 | D13: 34 | E13: 2 | F13: 12 | G13: 0 | H13: 1 | I13: 0 | J13: 3 | K13: 0 | L13: 0 | M13: 0 | N13: 50 | O13: 2
A14: 12 | B14: LICHTSTEINER Stephan | C14: 1 | D14: 14 | E14: 0 | F14: 6 | G14: 0 | H14: 1 | I14: 0 | J14: 2 | K14: 1 | L14: 0 | M14: 0 | N14: 23 | O14: 1
A15: 13 | B15: OSPINA David | C15: 5 | D15: 0 | E15: 0 | F15: 0 | G15: 0 | H15: 0 | I15: 0 | J15: 0 | K15: 0 | L15: 0 | M15: 0 | N15: 0 | O15: 0
... A43: 87 | B43: SAKA Bukayo | C43: 1 | D43: 1 | E43: 0 | F43: 2 | G43: 0 | H43: 1 | I43: 0 | J43: 0 | K43: 0 | L43: 0 | M43: 0 | N43: 4 | O43: 0

Sheet Apps & Goals 19-20
A1: Arsenal FC squad statistics
D2: Premier League | F2: Europa League | H2: FA Cup | J2: EFL Cup | L2: Community Shield | N2: Total
A3: # | B3: Name | C3: S | D3: Apps | E3: Goals | F3: Apps | G3: Goals | H3: Apps | I3: Goals | J3: Apps | K3: Goals | L3: Apps | M3: Goals | N3: Apps | O3: Goals
A4: 1 | B4: LENO Berndt | C4: 1 | D4: 30 | E4: 0 | F4: 2 | G4: 0 | H4: 0 | I4: 0 | J4: 0 | K4: 0 | L4: 0 | M4: 0 | N4: 32 | O4: 0
A5: 2 | B5: BELLERIN Hector | C5: 6 | D5: 15 | E5: 1 | F5: 3 | G5: 0 | H5: 3 | I5: 0 | J5: 2 | K5: 0 | L5: 0 | M5: 0 | N5: 23 | O5: 1
A6: 3 | B6: TIERNEY Kieran | C6: 1 | D6: 15 | E6: 1 | F6: 4 | G6: 0 | H6: 3 | I6: 0 | J6: 2 | K6: 0 | L6: 0 | M6: 0 | N6: 24 | O6: 1
A7: 4 | B7: ELNENY Mohamed | C7: 4 | D7: 0 | E7: 0 | F7: 0 | G7: 0 | H7: 0 | I7: 0 | J7: 0 | K7: 0 | L7: 0 | M7: 0 | N7: 0 | O7: 0
A8: 5 | B8: PAPASTATHOPULOS Sokratis | C8: 1 | D8: 19 | E8: 2 | F8: 5 | G8: 0 | H8: 5 | I8: 1 | J8: 0 | K8: 0 | L8: 0 | M8: 0 | N8: 29 | O8: 3
A9: 7 | B9: MKHITARYAN Henrikh | C9: 2 | D9: 3 | E9: 0 | F9: 0 | G9: 0 | H9: 0 | I9: 0 | J9: 0 | K9: 0 | L9: 0 | M9: 0 | N9: 3 | O9: 0
A10: 8 | B10: CEBALLOS Dani | C10: 1 | D10: 24 | E10: 0 | F10: 6 | G10: 1 | H10: 5 | I10: 1 | J10: 2 | K10: 0 | L10: 0 | M10: 0 | N10: 37 | O10: 2
A11: 9 | B11: LACAZETTE Alexandre | C11: 2 | D11: 30 | E11: 10 | F11: 5 | G11: 2 | H11: 4 | I11: 0 | J11: 0 | K11: 0 | L11: 0 | M11: 0 | N11: 39 | O11: 12
A12: 10 | B12: OZIL Mesut | C12: 6 | D12: 18 | E12: 1 | F12: 2 | G12: 0 | H12: 1 | I12: 0 | J12: 2 | K12: 0 | L12: 0 | M12: 0 | N12: 23 | O12: 1
A13: 11 | B13: TORREIRA Lucas | C13: 1 | D13: 29 | E13: 1 | F13: 6 | G13: 0 | H13: 1 | I13: 0 | J13: 2 | K13: 1 | L13: 0 | M13: 0 | N13: 38 | O13: 2
A14: 14 | B14: AUBAMEYANG Pierre-Emerick | C14: 2 | D14: 36 | E14: 22 | F14: 6 | G14: 3 | H14: 2 | I14: 4 | J14: 0 | K14: 0 | L14: 0 | M14: 0 | N14: 44 | O14: 29
A15: 15 | B15: MAITLAND-NILES Ainsley | C15: 5 | D15: 20 | E15: 0 | F15: 6 | G15: 0 | H15: 5 | I15: 0 | J15: 1 | K15: 1 | L15: 0 | M15: 0 | N15: 32 | O15: 1
... A36: 77 | B36: SAKA Bukayo | C36: 1 | D36: 26 | E36: 1 | F36: 6 | G36: 2 | H36: 4 | I36: 1 | J36: 2 | K36: 0 | L36: 0 | M36: 0 | N36: 38 | O36: 4

Sheet Apps & Goals 20-21
A1: Arsenal FC squad statistics
C2: Premier League | E2: Europa League | G2: FA Cup | I2: EFL Cup | K2: Community Shield | M2: Total
A3: # | B3: Name | C3: Apps | D3: Goals | E3: Apps | F3: Goals | G3: Apps | H3: Goals | I3: Apps | J3: Goals | K3: Apps | L3: Goals | M3: Apps | N3: Goals
A4: 1 | B4: LENO Berndt | C4: 35 | D4: 0 | E4: 10 | F4: 0 | G4: 2 | H4: 0 | I4: 2 | J4: 0 | K4: 0 | L4: 0 | M4: 49 | N4: 0
A5: 2 | B5: BELLERIN Hector | C5: 25 | D5: 1 | E5: 7 | F5: 0 | G5: 1 | H5: 0 | I5: 1 | J5: 0 | K5: 1 | L5: 0 | M5: 35 | N5: 1
A6: 3 | B6: TIERNEY Kieran | C6: 27 | D6: 1 | E6: 8 | F6: 1 | G6: 1 | H6: 0 | I6: 0 | J6: 0 | K6: 1 | L6: 0 | M6: 37 | N6: 2
A7: 4 | B7: SALIBA William | C7: 0 | D7: 0 | E7: 0 | F7: 0 | G7: 0 | H7: 0 | I7: 0 | J7: 0 | K7: 0 | L7: 0 | M7: 0 | N7: 0
A8: 6 | B8: GABRIEL | C8: 23 | D8: 2 | E8: 6 | F8: 1 | G8: 1 | H8: 0 | I8: 2 | J8: 0 | K8: 0 | L8: 0 | M8: 32 | N8: 3
A9: 7 | B9: SAKA Bukayo | C9: 32 | D9: 5 | E9: 9 | F9: 2 | G9: 2 | H9: 0 | I9: 2 | J9: 0 | K9: 1 | L9: 0 | M9: 46 | N9: 7
A10: 8 | B10: CEBALLOS Dani | C10: 24 | D10: 0 | E10: 12 | F10: 0 | G10: 0 | H10: 0 | I10: 3 | J10: 0 | K10: 0 | L10: 0 | M10: 39 | N10: 0
A11: 9 | B11: LACAZETTE Alexandre | C11: 31 | D11: 13 | E11: 8 | F11: 3 | G11: 2 | H11: 0 | I11: 2 | J11: 1 | K11: 0 | L11: 0 | M11: 43 | N11: 17
A12: 11 | B12: TORREIRA Lucas | C12: 0 | D12: 0 | E12: 0 | F12: 0 | G12: 0 | H12: 0 | I12: 0 | J12: 0 | K12: 0 | L12: 0 | M12: 0 | N12: 0
A13: 11 | B13: ODEGAARD Martin | C13: 14 | D13: 1 | E13: 6 | F13: 1 | G13: 0 | H13: 0 | I13: 0 | J13: 0 | K13: 0 | L13: 0 | M13: 20 | N13: 2
A14: 12 | B14: WILLIAN | C14: 25 | D14: 1 | E14: 9 | F14: 0 | G14: 2 | H14: 0 | I14: 1 | J14: 0 | K14: 0 | L14: 0 | M14: 37 | N14: 1
A15: 13 | B15: RUNARSSON Runar | C15: 1 | D15: 0 | E15: 4 | F15: 0 | G15: 0 | H15: 0 | I15: 1 | J15: 0 | K15: 0 | L15: 0 | M15: 6 | N15: 0
... A40: 66 | B40: AZEEZ Miguel | C40: 0 | D40: 0 | E40: 1 | F40: 0 | G40: 0 | H40: 0 | I40: 0 | J40: 0 | K40: 0 | L40: 0 | M40: 1 | N40: 0

Sheet Apps & Goals 21-22
A1: Arsenal FC squad statistics
C2: Premier League | E2: Europa League | G2: FA Cup | I2: EFL Cup | K2: Community Shield | M2: Total
A3: # | B3: Name | C3: Apps | D3: Goals | E3: Apps | F3: Goals | G3: Apps | H3: Goals | I3: Apps | J3: Goals | K3: Apps | L3: Goals | M3: Apps | N3: Goals
A4: 1 | B4: LENO Berndt | C4: 4 | D4: 0 | E4: 0 | F4: 0 | G4: 1 | H4: 0 | I4: 3 | J4: 0 | K4: 0 | L4: 0 | M4: 8 | N4: 0
A5: 2 | B5: BELLERIN Hector | C5: 0 | D5: 0 | E5: 0 | F5: 0 | G5: 0 | H5: 0 | I5: 0 | J5: 0 | K5: 0 | L5: 0 | M5: 0 | N5: 0
A6: 3 | B6: TIERNEY Kieran | C6: 22 | D6: 1 | E6: 0 | F6: 0 | G6: 1 | H6: 0 | I6: 2 | J6: 0 | K6: 0 | L6: 0 | M6: 25 | N6: 1
A7: 4 | B7: WHITE Ben | C7: 32 | D7: 0 | E7: 0 | F7: 0 | G7: 0 | H7: 0 | I7: 4 | J7: 0 | K7: 0 | L7: 0 | M7: 36 | N7: 0
A8: 5 | B8: PARTEY Thomas | C8: 24 | D8: 2 | E8: 0 | F8: 0 | G8: 0 | H8: 0 | I8: 2 | J8: 0 | K8: 0 | L8: 0 | M8: 26 | N8: 2
A9: 6 | B9: GABRIEL | C9: 35 | D9: 5 | E9: 0 | F9: 0 | G9: 0 | H9: 0 | I9: 3 | J9: 0 | K9: 0 | L9: 0 | M9: 38 | N9: 5
A10: 7 | B10: SAKA Bukayo | C10: 38 | D10: 11 | E10: 0 | F10: 0 | G10: 0 | H10: 0 | I10: 4 | J10: 1 | K10: 0 | L10: 0 | M10: 42 | N10: 12
A11: 8 | B11: ODEGAARD Martin | C11: 36 | D11: 7 | E11: 0 | F11: 0 | G11: 0 | H11: 0 | I11: 3 | J11: 0 | K11: 0 | L11: 0 | M11: 39 | N11: 7
A12: 9 | B12: LACAZETTE Alexandre | C12: 30 | D12: 4 | E12: 0 | F12: 0 | G12: 1 | H12: 0 | I12: 5 | J12: 2 | K12: 0 | L12: 0 | M12: 36 | N12: 6
A13: 10 | B13: SMITH-ROWE Emile | C13: 34 | D13: 10 | E13: 0 | F13: 0 | G13: 1 | H13: 0 | I13: 4 | J13: 1 | K13: 0 | L13: 0 | M13: 39 | N13: 11
A14: 11 | B14: TORREIRA Lucas | C14: 0 | D14: 0 | E14: 0 | F14: 0 | G14: 0 | H14: 0 | I14: 0 | J14: 0 | K14: 0 | L14: 0 | M14: 0 | N14: 0
A15: 13 | B15: RUNARSSON Runar | C15: 0 | D15: 0 | E15: 0 | F15: 0 | G15: 0 | H15: 0 | I15: 0 | J15: 0 | K15: 0 | L15: 0 | M15: 0 | N15: 0
... A36: 87 | B36: PATINO Charlie | C36: 0 | D36: 0 | E36: 0 | F36: 0 | G36: 1 | H36: 0 | I36: 1 | J36: 1 | K36: 0 | L36: 0 | M36: 2 | N36: 1

Sheet Apps & Goals 22-23
A1: Arsenal FC squad statistics
C2: Premier League | E2: Europa League | G2: FA Cup | I2: EFL Cup | K2: Community Shield | M2: Total
A3: # | B3: Name | C3: Apps | D3: Goals | E3: Apps | F3: Goals | G3: Apps | H3: Goals | I3: Apps | J3: Goals | K3: Apps | L3: Goals | M3: Apps | N3: Goals
A4: 1 | B4: RAMSDALE Aaron | C4: 38 | D4: 0 | E4: 3 | F4: 0 | G4: 0 | H4: 0 | I4: 0 | J4: 0 | K4: 0 | L4: 0 | M4: 41 | N4: 0
A5: 3 | B5: TIERNEY Kieran | C5: 27 | D5: 0 | E5: 6 | F5: 1 | G5: 2 | H5: 0 | I5: 1 | J5: 0 | K5: 0 | L5: 0 | M5: 36 | N5: 1
A6: 4 | B6: WHITE Ben | C6: 38 | D6: 2 | E6: 7 | F6: 0 | G6: 1 | H6: 0 | I6: 0 | J6: 0 | K6: 0 | L6: 0 | M6: 46 | N6: 2
A7: 5 | B7: PARTEY Thomas | C7: 33 | D7: 3 | E7: 6 | F7: 0 | G7: 1 | H7: 0 | I7: 0 | J7: 0 | K7: 0 | L7: 0 | M7: 40 | N7: 3
A8: 6 | B8: GABRIEL | C8: 38 | D8: 3 | E8: 7 | F8: 0 | G8: 2 | H8: 0 | I8: 1 | J8: 0 | K8: 0 | L8: 0 | M8: 48 | N8: 3
A9: 7 | B9: SAKA Bukayo | C9: 38 | D9: 14 | E9: 8 | F9: 1 | G9: 2 | H9: 0 | I9: 0 | J9: 0 | K9: 0 | L9: 0 | M9: 48 | N9: 15
A10: 8 | B10: ODEGAARD Martin | C10: 37 | D10: 15 | E10: 7 | F10: 0 | G10: 1 | H10: 0 | I10: 0 | J10: 0 | K10: 0 | L10: 0 | M10: 45 | N10: 15
A11: 9 | B11: JESUS Gabriel | C11: 26 | D11: 11 | E11: 6 | F11: 0 | G11: 0 | H11: 0 | I11: 1 | J11: 0 | K11: 0 | L11: 0 | M11: 33 | N11: 11
A12: 10 | B12: SMITH-ROWE Emile | C12: 12 | D12: 0 | E12: 1 | F12: 0 | G12: 1 | H12: 0 | I12: 0 | J12: 0 | K12: 0 | L12: 0 | M12: 14 | N12: 0
A13: 11 | B13: MARTINELLI Gabriel | C13: 36 | D13: 15 | E13: 6 | F13: 0 | G13: 2 | H13: 0 | I13: 1 | J13: 0 | K13: 0 | L13: 0 | M13: 45 | N13: 15
A14: 12 | B14: SALIBA William | C14: 27 | D14: 2 | E14: 4 | F14: 1 | G14: 1 | H14: 0 | I14: 1 | J14: 0 | K14: 0 | L14: 0 | M14: 33 | N14: 3
A15: 13 | B15: RUNARSSON Runar | C15: 0 | D15: 0 | E15: 0 | F15: 0 | G15: 0 | H15: 0 | I15: 0 | J15: 0 | K15: 0 | L15: 0 | M15: 0 | N15: 0
... A41: 87 | B41: PATINO Charlie | C41: 0 | D41: 0 | E41: 0 | F41: 0 | G41: 0 | H41: 0 | I41: 0 | J41: 0 | K41: 0 | L41: 0 | M41: 0 | N41: 0

Sheet Apps & Goals 23-24
A1: Arsenal FC squad statistics
C2: Premier League | E2: Europe | G2: FA Cup | I2: EFL Cup | K2: Community Shield | M2: Total
A3: # | B3: Name | C3: Apps | D3: Goals | E3: Apps | F3: Goals | G3: Apps | H3: Goals | I3: Apps | J3: Goals | K3: Apps | L3: Goals | M3: Apps | N3: Goals
A4: 1 | B4: RAMSDALE Aaron | C4: 6 | D4: 0 | E4: 1 | F4: 0 | G4: 1 | H4: 0 | I4: 2 | J4: 0 | K4: 1 | L4: 0 | M4: 11 | N4: 0
A5: 2 | B5: SALIBA William | C5: 38 | D5: 2 | E5: 10 | F5: 0 | G5: 1 | H5: 0 | I5: 0 | J5: 0 | K5: 1 | L5: 0 | M5: 50 | N5: 2
A6: 3 | B6: TIERNEY Kieran | C6: 0 | D6: 0 | E6: 0 | F6: 0 | G6: 0 | H6: 0 | I6: 0 | J6: 0 | K6: 1 | L6: 0 | M6: 1 | N6: 0
A7: 4 | B7: WHITE Ben | C7: 37 | D7: 4 | E7: 10 | F7: 0 | G7: 1 | H7: 0 | I7: 2 | J7: 0 | K7: 1 | L7: 0 | M7: 51 | N7: 4
A8: 5 | B8: PARTEY Thomas | C8: 14 | D8: 0 | E8: 1 | F8: 0 | G8: 0 | H8: 0 | I8: 0 | J8: 0 | K8: 1 | L8: 0 | M8: 16 | N8: 0
A9: 6 | B9: GABRIEL | C9: 36 | D9: 4 | E9: 10 | F9: 0 | G9: 1 | H9: 0 | I9: 2 | J9: 0 | K9: 1 | L9: 0 | M9: 50 | N9: 4
A10: 7 | B10: SAKA Bukayo | C10: 35 | D10: 16 | E10: 9 | F10: 4 | G10: 1 | H10: 0 | I10: 1 | J10: 0 | K10: 1 | L10: 0 | M10: 47 | N10: 20
A11: 8 | B11: ODEGAARD Martin | C11: 35 | D11: 8 | E11: 9 | F11: 2 | G11: 1 | H11: 0 | I11: 2 | J11: 1 | K11: 1 | L11: 0 | M11: 48 | N11: 11
A12: 9 | B12: JESUS Gabriel | C12: 27 | D12: 4 | E12: 8 | F12: 4 | G12: 0 | H12: 0 | I12: 1 | J12: 0 | K12: 0 | L12: 0 | M12: 36 | N12: 8
A13: 10 | B13: SMITH-ROWE Emile | C13: 13 | D13: 0 | E13: 3 | F13: 0 | G13: 1 | H13: 0 | I13: 1 | J13: 0 | K13: 1 | L13: 0 | M13: 19 | N13: 0
A14: 11 | B14: MARTINELLI Gabriel | C14: 35 | D14: 6 | E14: 7 | F14: 2 | G14: 1 | H14: 0 | I14: 1 | J14: 0 | K14: 1 | L14: 0 | M14: 45 | N14: 8
A15: 12 | B15: TIMBER Jurrien | C15: 2 | D15: 0 | E15: 0 | F15: 0 | G15: 0 | H15: 0 | I15: 0 | J15: 0 | K15: 1 | L15: 0 | M15: 3 | N15: 0
... A38: 87 | B38: PATINO Charlie | C38: 0 | D38: 0 | E38: 0 | F38: 0 | G38: 0 | H38: 0 | I38: 0 | J38: 0 | K38: 0 | L38: 0 | M38: 0 | N38: 0

Sheet Apps & Goals 24-25
A1: Arsenal FC squad statistics
C2: Premier League | E2: Europe | G2: FA Cup | I2: EFL Cup | K2: Community Shield | M2: Total
A3: # | B3: Name | C3: Apps | D3: Goals | E3: Apps | F3: Goals | G3: Apps | H3: Goals | I3: Apps | J3: Goals | K3: Apps | L3: Goals | M3: Apps | N3: Goals
A4: 2 | B4: SALIBA William | C4: 35 | D4: 2 | E4: 10 | F4: 0 | G4: 1 | H4: 0 | I4: 4 | J4: 0 | K4: 0 | L4: 0 | M4: 50 | N4: 2
A5: 3 | B5: TIERNEY Kieran | C5: 13 | D5: 1 | E5: 5 | F5: 0 | G5: 1 | H5: 0 | I5: 1 | J5: 0 | K5: 0 | L5: 0 | M5: 20 | N5: 1
A6: 4 | B6: WHITE Ben | C6: 17 | D6: 0 | E6: 9 | F6: 0 | G6: 0 | H6: 0 | I6: 0 | J6: 0 | K6: 0 | L6: 0 | M6: 26 | N6: 0
A7: 5 | B7: PARTEY Thomas | C7: 34 | D7: 4 | E7: 10 | F7: 0 | G7: 1 | H7: 0 | I7: 4 | J7: 0 | K7: 0 | L7: 0 | M7: 49 | N7: 4
A8: 6 | B8: GABRIEL | C8: 28 | D8: 3 | E8: 8 | F8: 1 | G8: 1 | H8: 1 | I8: 3 | J8: 0 | K8: 0 | L8: 0 | M8: 40 | N8: 5
A9: 7 | B9: SAKA Bukayo | C9: 25 | D9: 6 | E9: 8 | F9: 4 | G9: 0 | H9: 0 | I9: 3 | J9: 0 | K9: 0 | L9: 0 | M9: 36 | N9: 10
A10: 8 | B10: ODEGAARD Martin | C10: 31 | D10: 3 | E10: 9 | F10: 3 | G10: 1 | H10: 0 | I10: 3 | J10: 0 | K10: 0 | L10: 0 | M10: 44 | N10: 6
A11: 9 | B11: JESUS Gabriel | C11: 17 | D11: 3 | E11: 5 | F11: 0 | G11: 1 | H11: 0 | I11: 4 | J11: 4 | K11: 0 | L11: 0 | M11: 27 | N11: 7
A12: 11 | B12: MARTINELLI Gabriel | C12: 34 | D12: 8 | E12: 11 | F12: 2 | G12: 1 | H12: 0 | I12: 4 | J12: 0 | K12: 0 | L12: 0 | M12: 50 | N12: 10
A13: 12 | B13: TIMBER Jurrien | C13: 30 | D13: 1 | E13: 11 | F13: 1 | G13: 1 | H13: 0 | I13: 4 | J13: 0 | K13: 0 | L13: 0 | M13: 46 | N13: 2
A14: 15 | B14: KIWIOR Jakub | C14: 17 | D14: 1 | E14: 8 | F14: 0 | G14: 0 | H14: 0 | I14: 3 | J14: 0 | K14: 0 | L14: 0 | M14: 28 | N14: 1
A15: 17 | B15: ZINCHENKO Oleksandr | C15: 15 | D15: 0 | E15: 6 | F15: 1 | G15: 0 | H15: 0 | I15: 2 | J15: 0 | K15: 0 | L15: 0 | M15: 23 | N15: 1
... A41: 92 | B41: PORTER Jack | C41: 0 | D41: 0 | E41: 0 | F41: 0 | G41: 0 | H41: 0 | I41: 1 | J41: 0 | K41: 0 | L41: 0 | M41: 1 | N41: 0

Sheet Apps & Goals 25-26
A1: Arsenal FC squad statistics
C2: Premier League | E2: Europe | G2: FA Cup | I2: EFL Cup | K2: Community Shield | M2: Total
A3: # | B3: Name | C3: Apps | D3: Goals | E3: Apps | F3: Goals | G3: Apps | H3: Goals | I3: Apps | J3: Goals | K3: Apps | L3: Goals | M3: Apps | N3: Goals
A4: 1 | B4: RAYA David | C4: 37 | D4: 0 | E4: 14 | F4: 0 | G4: 0 | H4: 0 | I4: 0 | J4: 0 | K4: 0 | L4: 0 | M4: 51 | N4: 0
A5: 2 | B5: SALIBA William | C5: 31 | D5: 1 | E5: 12 | F5: 0 | G5: 2 | H5: 0 | I5: 5 | J5: 0 | K5: 0 | L5: 0 | M5: 50 | N5: 1
A6: 3 | B6: MOSQUERA Cristhian | C6: 20 | D6: 0 | E6: 10 | F6: 0 | G6: 3 | H6: 0 | I6: 2 | J6: 0 | K6: 0 | L6: 0 | M6: 35 | N6: 0
A7: 4 | B7: WHITE Ben | C7: 12 | D7: 0 | E7: 10 | F7: 0 | G7: 3 | H7: 0 | I7: 4 | J7: 1 | K7: 0 | L7: 0 | M7: 29 | N7: 1
A8: 5 | B8: HINCAPIE Piero | C8: 25 | D8: 1 | E8: 9 | F8: 0 | G8: 1 | H8: 0 | I8: 3 | J8: 0 | K8: 0 | L8: 0 | M8: 38 | N8: 1
A9: 6 | B9: GABRIEL | C9: 32 | D9: 3 | E9: 12 | F9: 1 | G9: 2 | H9: 0 | I9: 5 | J9: 0 | K9: 0 | L9: 0 | M9: 51 | N9: 4
A10: 7 | B10: SAKA Bukayo | C10: 31 | D10: 7 | E10: 11 | F10: 3 | G10: 2 | H10: 0 | I10: 5 | J10: 1 | K10: 0 | L10: 0 | M10: 49 | N10: 11
A11: 8 | B11: ODEGAARD Martin | C11: 24 | D11: 1 | E11: 7 | F11: 0 | G11: 2 | H11: 0 | I11: 2 | J11: 0 | K11: 0 | L11: 0 | M11: 35 | N11: 1
A12: 9 | B12: JESUS Gabriel | C12: 14 | D12: 3 | E12: 6 | F12: 2 | G12: 4 | H12: 1 | I12: 3 | J12: 0 | K12: 0 | L12: 0 | M12: 27 | N12: 6
A13: 10 | B13: EZE Eberechi | C13: 32 | D13: 6 | E13: 13 | F13: 1 | G13: 3 | H13: 1 | I13: 4 | J13: 1 | K13: 0 | L13: 0 | M13: 52 | N13: 9
A14: 11 | B14: MARTINELLI Gabriel | C14: 29 | D14: 1 | E14: 13 | F14: 6 | G14: 4 | H14: 4 | I14: 5 | J14: 0 | K14: 0 | L14: 0 | M14: 51 | N14: 11
A15: 12 | B15: TIMBER Jurrien | C15: 30 | D15: 3 | E15: 8 | F15: 1 | G15: 2 | H15: 0 | I15: 4 | J15: 0 | K15: 0 | L15: 0 | M15: 44 | N15: 4
... A42: 92 | B42: PORTER Jack | C42: 0 | D42: 0 | E42: 0 | F42: 0 | G42: 0 | H42: 0 | I42: 0 | J42: 0 | K42: 0 | L42: 0 | M42: 0 | N42: 0

Sheet Apps & Goals 26-27
A1: Arsenal FC squad statistics
C2: Premier League | F2: Europe | I2: FA Cup | L2: EFL Cup | O2: Community Shield | R2: Total
A3: # | B3: Name | C3: App | D3: Gls | E3: Ast | F3: App | G3: Gls | H3: Ast | I3: App | J3: Gls | K3: Ast | L3: App | M3: Gls | N3: Ast | O3: App | P3: Gls | Q3: Ast | R3: App | S3: Gls | T3: Ast
A4: 1 | B4: RAYA David | C4: ='Premier League'!C4 -> 6 | D4: ='Premier League'!D4 -> 0 | E4: ='Premier League'!E4 -> 0 | F4: =Europe!C4 -> 1 | G4: =Europe!D4 -> 0 | H4: =Europe!E4 -> 0 | I4: ='FA Cup'!C4 -> 0 | J4: ='FA Cup'!D4 -> 0 | K4: ='FA Cup'!E4 -> 0 | L4: ='League Cup'!C4 -> 0 | M4: ='League Cup'!D4 -> 0 | N4: ='League Cup'!E4 -> 0 | O4: ='Other (CS)'!C3 -> 1 | P4: ='Other (CS)'!D3 -> 0 | Q4: ='Other (CS)'!E3 -> 0 | R4: =SUM(C4,F4,I4,L4,O4) -> 8 | S4: =SUM(D4,G4,J4,M4,P4) -> 0 | T4: =SUM(E4,H4,K4,N4,Q4) -> 0
A5: 2 | B5: SALIBA William | C5: ='Premier League'!C5 -> 0 | D5: ='Premier League'!D5 -> 0 | E5: ='Premier League'!E5 -> 0 | F5: =Europe!C5 -> 0 | G5: =Europe!D5 -> 0 | H5: =Europe!E5 -> 0 | I5: ='FA Cup'!C5 -> 0 | J5: ='FA Cup'!D5 -> 0 | K5: ='FA Cup'!E5 -> 0 | L5: ='League Cup'!C5 -> 0 | M5: ='League Cup'!D5 -> 0 | N5: ='League Cup'!E5 -> 0 | O5: ='Other (CS)'!C4 -> 0 | P5: ='Other (CS)'!D4 -> 0 | Q5: ='Other (CS)'!E4 -> 0 | R5: =SUM(C5,F5,I5,L5,O5) -> 0 | S5: =SUM(D5,G5,J5,M5,P5) -> 0 | T5: =SUM(E5,H5,K5,N5,Q5) -> 0
